Workbook

Sheet README
A1: Porsche Company Lens - 2026 Margin Recovery: business-analysis workbook
A2: Phase 5 (Excel). Built from the validated PostgreSQL database porsche_lens (Phases 3-4). Prepared 2026-09-28.
A4: Question | B4: Porsche's reported margin rose from 5.5% to 7.8% in H1 2026. After removing the exceptional items Porsche itself discloses, and isolating non-cash effects from R&D capitalisation and depreciation, is underlying profitability actually improving, and what does FY2026 guidance imply for H2 2026?
A5: Purpose | B5: A transparent, formula-driven model that a business team can audit: every number traces back to a Porsche document and page.
A6: Model status | B6: =IF(COUNTIF(Audit_Checks!$H$7:$H$56,"FAIL")=0,"ALL "&COUNTA(Audit_Checks!$H$7:$H$56)&" CHECKS PASS",COUNTIF(Audit_Checks!$H$7:$H$56,"FAIL")&" OF "&COUNTA(Audit_Checks!$H$7:$H$56)&" CHECK(S) FAIL - see Audit_Checks") -> ALL 50 CHECKS PASS
A8: SHEET MAP | B8: What each sheet answers
A9: KPI_Overview | B9: What happened? Headline KPIs by half-year, H1 2025 vs H1 2026, formula-driven readings, two charts.
A10: EBIT_Analysis | B10: Is underlying profitability improving? Reported (L0) vs adjusted (L1, L2) EBIT and margin; own YoY bridge in EUR m and pp; reconciliation to Porsche's bridge. L3 in a grey supplementary box.
A11: RD_DA | B11: Are non-cash effects flattering EBIT? Total R&D costs, capitalisation rate, P&L charge, counterfactual; D&A cleaned of impairments.
A12: Commercial | B12: Is value compensating for volume? ASP (Porsche definition), vehicle sales, volume vs ASP effect, model and regional mix.
A13: Cash_Crosscheck | B13: Does cash confirm the profit picture? EBIT/EBITDA vs net cash flow, published-margin reconciliation, simple cash proxy.
A14: Guidance_Scenarios | B14: What must H2 2026 look like to meet guidance? Scenario selector + all 27 combinations + automotive view. Scenarios, NOT forecasts.
A15: Audit_Checks | B15: Can the numbers be trusted? 50 formula checks: imports, lookup integrity (unique keys + panel round-trip), Excel vs SQL reconciliation, identities, Porsche reconciliation, labelling, and 8 anchor values displayed on KPI_Overview vs the SQL export.
A16: Audit_Register | B16: Where does it come from? Source register, assumptions A-01..A-09, known data gaps, audit findings, SQL view catalogue, SQL check results.
A17: Data_Panel | B17: Half-year panel (formula pivot of Data_Long) with a FACT/DERIVED label grid; derived cells shaded.
A18: Data_Long / Data_Mix | B18: Controlled imports from SQL (core.fact_financial, deliveries). The only place where Porsche values are typed in.
A19: SQL_Outputs | B19: Mart view results, used ONLY by Audit_Checks to prove that Excel and SQL agree.
A21: CONVENTIONS
A22: Colours | B22: Blue = imported or hard-coded input. Black = formula. Green = link to another sheet. Yellow fill = headline KPI. Grey fill = supplementary sensitivity. Orange band = scenario area.
A23: Units | B23: Money in EUR m. Margins stored as fractions and shown as %. 'pp' = percentage points. ASP in EUR k. Volumes in units.
A24: Signs | B24: Exceptional items and tariffs are positive numbers = expense; adding them back raises EBIT. Bridge effects: + = raises EBIT.
A25: Periods | B25: Half-years 2023-H1 .. 2026-H1. Porsche publishes H1 and FY; H2 = FY - H1 (DERIVED in SQL). Year-on-year always compares the same half of the prior year.
A26: FACT / DERIVED | B26: FACT = published by Porsche. DERIVED = calculated from published values (H2, identities, FY2025 one-off total). See Data_Panel label grid and Data_Long source_ref.
A28: PROFIT LEVELS
A29: L0 (headline) | B29: Reported group EBIT.
A30: L1 (headline) | B30: L0 + strategic realignment & battery items as disclosed by Porsche (net of related provision releases).
A31: L2 (headline) | B31: L1 + US import tariffs.
A32: L3 (supplementary) | B32: Supplementary HYBRID SENSITIVITY only: L1 + clean automotive D&A - automotive capitalised development costs. Not underlying group profitability; never used as headline KPI.
A33: Residual | B33: 'Residual / other EBIT drivers' in the bridge is NOT operating performance: it mixes price, mix, volume, total R&D cost changes, material/supplier costs, SG&A, other operating result, FX, consolidation and one-off rounding.
A35: KEY ASSUMPTIONS | B35: Full register: Audit_Register section 2.
A36: A-01 / A-02 | B36: No realignment items disclosed for 2023-2024 and no US tariffs before April 2025 -> treated as 0.
A37: A-03 / A-04 | B37: Undisclosed impairments (H2 2023, H2 2024) -> 0; H1 2026 impairments (EUR 61m) assumed inside D&A (alternative shown).
A38: A-05..A-08 | B38: Guidance: automotive revenue share, extraordinary-expense basis, H2 tariffs = H1, range ends combined independently.
A39: A-09 | B39: Derived H2 values inherit the EUR 0.1bn rounding of one-off disclosures (rounding band shown).
A41: LINEAGE | B41: Porsche documents (S001-S027) -> PCL_02_Manual_Inputs.xlsx + fact sheet S025 -> PostgreSQL core.fact_financial -> mart views -> Data_Long (this workbook) -> analysis sheets. Refresh: re-export fact_long / mix / SQL outputs and replace the blue import rows; Audit_Checks must show ALL PASS.
A42: Not in scope | B42: No forecasts, no internal Porsche data, no estimates for missing values. Interpretation and recommendations follow in Phases 6-9.

Sheet Data_Panel
A1: Data_Panel - half-year panel built by formula from Data_Long
A2: Each cell = two-criteria lookup on Data_Long: SUMIFS(value, period_code = column header, var_id = row id), guarded by COUNTIFS (0 matches -> blank; Data_Long!K proves each pair is unique). Blank = not published. Shaded cells are DERIVED (H2 = FY - H1 or identity); label grid below states FACT / DERIVED per cell.
A3: Money in EUR m; % variables as published (e.g. 18.3 = 18.3%). Analysis sheets convert.
A5: var_id | B5: variable | C5: unit | D5: 2023-H1 | E5: 2023-H2 | F5: 2024-H1 | G5: 2024-H2 | H5: 2025-H1 | I5: 2025-H2 | J5: 2026-H1 | K5: sources used (from Data_Long)
A6: G01 | B6: Group sales revenue | C6: EUR m | D6: =IF(COUNTIFS(Data_Long!$A$6:$A$243,D$5,Data_Long!$B$6:$B$243,$A6)=0,"",SUMIFS(Data_Long!$D$6:$D$243,Data_Long!$A$6:$A$243,D$5,Data_Long!$B$6:$B$243,$A6)) -> 20430.923 | E6: =IF(COUNTIFS(Data_Long!$A$6:$A$243,E$5,Data_Long!$B$6:$B$243,$A6)=0,"",SUMIFS(Data_Long!$D$6:$D$243,Data_Long!$A$6:$A$243,E$5,Data_Long!$B$6:$B$243,$A6)) -> 20098.71 | F6: =IF(COUNTIFS(Data_Long!$A$6:$A$243,F$5,Data_Long!$B$6:$B$243,$A6)=0,"",SUMIFS(Data_Long!$D$6:$D$243,Data_Long!$A$6:$A$243,F$5,Data_Long!$B$6:$B$243,$A6)) -> 19457.009 | G6: =IF(COUNTIFS(Data_Long!$A$6:$A$243,G$5,Data_Long!$B$6:$B$243,$A6)=0,"",SUMIFS(Data_Long!$D$6:$D$243,Data_Long!$A$6:$A$243,G$5,Data_Long!$B$6:$B$243,$A6)) -> 20626.284 | H6: =IF(COUNTIFS(Data_Long!$A$6:$A$243,H$5,Data_Long!$B$6:$B$243,$A6)=0,"",SUMIFS(Data_Long!$D$6:$D$243,Data_Long!$A$6:$A$243,H$5,Data_Long!$B$6:$B$243,$A6)) -> 18157.275 | I6: =IF(COUNTIFS(Data_Long!$A$6:$A$243,I$5,Data_Long!$B$6:$B$243,$A6)=0,"",SUMIFS(Data_Long!$D$6:$D$243,Data_Long!$A$6:$A$243,I$5,Data_Long!$B$6:$B$243,$A6)) -> 18114.353 | J6: =IF(COUNTIFS(Data_Long!$A$6:$A$243,J$5,Data_Long!$B$6:$B$243,$A6)=0,"",SUMIFS(Data_Long!$D$6:$D$243,Data_Long!$A$6:$A$243,J$5,Data_Long!$B$6:$B$243,$A6)) -> 17229.456 | K6: S025, SQL derived
A7: G02 | B7: Cost of sales | C7: EUR m | D7: =IF(COUNTIFS(Data_Long!$A$6:$A$243,D$5,Data_Long!$B$6:$B$243,$A7)=0,"",SUMIFS(Data_Long!$D$6:$D$243,Data_Long!$A$6:$A$243,D$5,Data_Long!$B$6:$B$243,$A7)) -> -14521.515 | E7: =IF(COUNTIFS(Data_Long!$A$6:$A$243,E$5,Data_Long!$B$6:$B$243,$A7)=0,"",SUMIFS(Data_Long!$D$6:$D$243,Data_Long!$A$6:$A$243,E$5,Data_Long!$B$6:$B$243,$A7)) -> -14402.255 | F7: =IF(COUNTIFS(Data_Long!$A$6:$A$243,F$5,Data_Long!$B$6:$B$243,$A7)=0,"",SUMIFS(Data_Long!$D$6:$D$243,Data_Long!$A$6:$A$243,F$5,Data_Long!$B$6:$B$243,$A7)) -> -14251.029 | G7: =IF(COUNTIFS(Data_Long!$A$6:$A$243,G$5,Data_Long!$B$6:$B$243,$A7)=0,"",SUMIFS(Data_Long!$D$6:$D$243,Data_Long!$A$6:$A$243,G$5,Data_Long!$B$6:$B$243,$A7)) -> -15504.837 | H7: =IF(COUNTIFS(Data_Long!$A$6:$A$243,H$5,Data_Long!$B$6:$B$243,$A7)=0,"",SUMIFS(Data_Long!$D$6:$D$243,Data_Long!$A$6:$A$243,H$5,Data_Long!$B$6:$B$243,$A7)) -> -14793.386 | I7: =IF(COUNTIFS(Data_Long!$A$6:$A$243,I$5,Data_Long!$B$6:$B$243,$A7)=0,"",SUMIFS(Data_Long!$D$6:$D$243,Data_Long!$A$6:$A$243,I$5,Data_Long!$B$6:$B$243,$A7)) -> -16427.364 | J7: =IF(COUNTIFS(Data_Long!$A$6:$A$243,J$5,Data_Long!$B$6:$B$243,$A7)=0,"",SUMIFS(Data_Long!$D$6:$D$243,Data_Long!$A$6:$A$243,J$5,Data_Long!$B$6:$B$243,$A7)) -> -13763.625 | K7: S025, SQL derived
A8: G03 | B8: Gross profit | C8: EUR m | D8: =IF(COUNTIFS(Data_Long!$A$6:$A$243,D$5,Data_Long!$B$6:$B$243,$A8)=0,"",SUMIFS(Data_Long!$D$6:$D$243,Data_Long!$A$6:$A$243,D$5,Data_Long!$B$6:$B$243,$A8)) -> 5909.4077 | E8: =IF(COUNTIFS(Data_Long!$A$6:$A$243,E$5,Data_Long!$B$6:$B$243,$A8)=0,"",SUMIFS(Data_Long!$D$6:$D$243,Data_Long!$A$6:$A$243,E$5,Data_Long!$B$6:$B$243,$A8)) -> 5696.4553 | F8: =IF(COUNTIFS(Data_Long!$A$6:$A$243,F$5,Data_Long!$B$6:$B$243,$A8)=0,"",SUMIFS(Data_Long!$D$6:$D$243,Data_Long!$A$6:$A$243,F$5,Data_Long!$B$6:$B$243,$A8)) -> 5205.9796 | G8: =IF(COUNTIFS(Data_Long!$A$6:$A$243,G$5,Data_Long!$B$6:$B$243,$A8)=0,"",SUMIFS(Data_Long!$D$6:$D$243,Data_Long!$A$6:$A$243,G$5,Data_Long!$B$6:$B$243,$A8)) -> 5121.4476 | H8: =IF(COUNTIFS(Data_Long!$A$6:$A$243,H$5,Data_Long!$B$6:$B$243,$A8)=0,"",SUMIFS(Data_Long!$D$6:$D$243,Data_Long!$A$6:$A$243,H$5,Data_Long!$B$6:$B$243,$A8)) -> 3363.8889 | I8: =IF(COUNTIFS(Data_Long!$A$6:$A$243,I$5,Data_Long!$B$6:$B$243,$A8)=0,"",SUMIFS(Data_Long!$D$6:$D$243,Data_Long!$A$6:$A$243,I$5,Data_Long!$B$6:$B$243,$A8)) -> 1686.989 | J8: =IF(COUNTIFS(Data_Long!$A$6:$A$243,J$5,Data_Long!$B$6:$B$243,$A8)=0,"",SUMIFS(Data_Long!$D$6:$D$243,Data_Long!$A$6:$A$243,J$5,Data_Long!$B$6:$B$243,$A8)) -> 3465.8305 | K8: S025, SQL derived
A9: G04 | B9: Distribution expenses | C9: EUR m | D9: =IF(COUNTIFS(Data_Long!$A$6:$A$243,D$5,Data_Long!$B$6:$B$243,$A9)=0,"",SUMIFS(Data_Long!$D$6:$D$243,Data_Long!$A$6:$A$243,D$5,Data_Long!$B$6:$B$243,$A9)) -> -1292.9307 | E9: =IF(COUNTIFS(Data_Long!$A$6:$A$243,E$5,Data_Long!$B$6:$B$243,$A9)=0,"",SUMIFS(Data_Long!$D$6:$D$243,Data_Long!$A$6:$A$243,E$5,Data_Long!$B$6:$B$243,$A9)) -> -1576.4607 | F9: =IF(COUNTIFS(Data_Long!$A$6:$A$243,F$5,Data_Long!$B$6:$B$243,$A9)=0,"",SUMIFS(Data_Long!$D$6:$D$243,Data_Long!$A$6:$A$243,F$5,Data_Long!$B$6:$B$243,$A9)) -> -1379.2659 | G9: =IF(COUNTIFS(Data_Long!$A$6:$A$243,G$5,Data_Long!$B$6:$B$243,$A9)=0,"",SUMIFS(Data_Long!$D$6:$D$243,Data_Long!$A$6:$A$243,G$5,Data_Long!$B$6:$B$243,$A9)) -> -1720.1293 | H9: =IF(COUNTIFS(Data_Long!$A$6:$A$243,H$5,Data_Long!$B$6:$B$243,$A9)=0,"",SUMIFS(Data_Long!$D$6:$D$243,Data_Long!$A$6:$A$243,H$5,Data_Long!$B$6:$B$243,$A9)) -> -1310.3138 | I9: =IF(COUNTIFS(Data_Long!$A$6:$A$243,I$5,Data_Long!$B$6:$B$243,$A9)=0,"",SUMIFS(Data_Long!$D$6:$D$243,Data_Long!$A$6:$A$243,I$5,Data_Long!$B$6:$B$243,$A9)) -> -1485.2685 | J9: =IF(COUNTIFS(Data_Long!$A$6:$A$243,J$5,Data_Long!$B$6:$B$243,$A9)=0,"",SUMIFS(Data_Long!$D$6:$D$243,Data_Long!$A$6:$A$243,J$5,Data_Long!$B$6:$B$243,$A9)) -> -1278.4594 | K9: S025, SQL derived
A10: G05 | B10: Administrative expenses | C10: EUR m | D10: =IF(COUNTIFS(Data_Long!$A$6:$A$243,D$5,Data_Long!$B$6:$B$243,$A10)=0,"",SUMIFS(Data_Long!$D$6:$D$243,Data_Long!$A$6:$A$243,D$5,Data_Long!$B$6:$B$243,$A10)) -> -875.09562 | E10: =IF(COUNTIFS(Data_Long!$A$6:$A$243,E$5,Data_Long!$B$6:$B$243,$A10)=0,"",SUMIFS(Data_Long!$D$6:$D$243,Data_Long!$A$6:$A$243,E$5,Data_Long!$B$6:$B$243,$A10)) -> -911.68941 | F10: =IF(COUNTIFS(Data_Long!$A$6:$A$243,F$5,Data_Long!$B$6:$B$243,$A10)=0,"",SUMIFS(Data_Long!$D$6:$D$243,Data_Long!$A$6:$A$243,F$5,Data_Long!$B$6:$B$243,$A10)) -> -951.8289 | G10: =IF(COUNTIFS(Data_Long!$A$6:$A$243,G$5,Data_Long!$B$6:$B$243,$A10)=0,"",SUMIFS(Data_Long!$D$6:$D$243,Data_Long!$A$6:$A$243,G$5,Data_Long!$B$6:$B$243,$A10)) -> -907.45239 | H10: =IF(COUNTIFS(Data_Long!$A$6:$A$243,H$5,Data_Long!$B$6:$B$243,$A10)=0,"",SUMIFS(Data_Long!$D$6:$D$243,Data_Long!$A$6:$A$243,H$5,Data_Long!$B$6:$B$243,$A10)) -> -977.85327 | I10: =IF(COUNTIFS(Data_Long!$A$6:$A$243,I$5,Data_Long!$B$6:$B$243,$A10)=0,"",SUMIFS(Data_Long!$D$6:$D$243,Data_Long!$A$6:$A$243,I$5,Data_Long!$B$6:$B$243,$A10)) -> -920.81009 | J10: =IF(COUNTIFS(Data_Long!$A$6:$A$243,J$5,Data_Long!$B$6:$B$243,$A10)=0,"",SUMIFS(Data_Long!$D$6:$D$243,Data_Long!$A$6:$A$243,J$5,Data_Long!$B$6:$B$243,$A10)) -> -997.07232 | K10: S025, SQL derived
A11: G06 | B11: Net other operating result | C11: EUR m | D11: =IF(COUNTIFS(Data_Long!$A$6:$A$243,D$5,Data_Long!$B$6:$B$243,$A11)=0,"",SUMIFS(Data_Long!$D$6:$D$243,Data_Long!$A$6:$A$243,D$5,Data_Long!$B$6:$B$243,$A11)) -> 110.85388 | E11: =IF(COUNTIFS(Data_Long!$A$6:$A$243,E$5,Data_Long!$B$6:$B$243,$A11)=0,"",SUMIFS(Data_Long!$D$6:$D$243,Data_Long!$A$6:$A$243,E$5,Data_Long!$B$6:$B$243,$A11)) -> 223.76728 | F11: =IF(COUNTIFS(Data_Long!$A$6:$A$243,F$5,Data_Long!$B$6:$B$243,$A11)=0,"",SUMIFS(Data_Long!$D$6:$D$243,Data_Long!$A$6:$A$243,F$5,Data_Long!$B$6:$B$243,$A11)) -> 186.57065 | G11: =IF(COUNTIFS(Data_Long!$A$6:$A$243,G$5,Data_Long!$B$6:$B$243,$A11)=0,"",SUMIFS(Data_Long!$D$6:$D$243,Data_Long!$A$6:$A$243,G$5,Data_Long!$B$6:$B$243,$A11)) -> 81.571308 | H11: =IF(COUNTIFS(Data_Long!$A$6:$A$243,H$5,Data_Long!$B$6:$B$243,$A11)=0,"",SUMIFS(Data_Long!$D$6:$D$243,Data_Long!$A$6:$A$243,H$5,Data_Long!$B$6:$B$243,$A11)) -> -68.930531 | I11: =IF(COUNTIFS(Data_Long!$A$6:$A$243,I$5,Data_Long!$B$6:$B$243,$A11)=0,"",SUMIFS(Data_Long!$D$6:$D$243,Data_Long!$A$6:$A$243,I$5,Data_Long!$B$6:$B$243,$A11)) -> 125.58225 | J11: =IF(COUNTIFS(Data_Long!$A$6:$A$243,J$5,Data_Long!$B$6:$B$243,$A11)=0,"",SUMIFS(Data_Long!$D$6:$D$243,Data_Long!$A$6:$A$243,J$5,Data_Long!$B$6:$B$243,$A11)) -> 157.88631 | K11: S025, SQL derived
A12: G07 | B12: Operating profit (EBIT), group | C12: EUR m | D12: =IF(COUNTIFS(Data_Long!$A$6:$A$243,D$5,Data_Long!$B$6:$B$243,$A12)=0,"",SUMIFS(Data_Long!$D$6:$D$243,Data_Long!$A$6:$A$243,D$5,Data_Long!$B$6:$B$243,$A12)) -> 3852.2352 | E12: =IF(COUNTIFS(Data_Long!$A$6:$A$243,E$5,Data_Long!$B$6:$B$243,$A12)=0,"",SUMIFS(Data_Long!$D$6:$D$243,Data_Long!$A$6:$A$243,E$5,Data_Long!$B$6:$B$243,$A12)) -> 3432.0724 | F12: =IF(COUNTIFS(Data_Long!$A$6:$A$243,F$5,Data_Long!$B$6:$B$243,$A12)=0,"",SUMIFS(Data_Long!$D$6:$D$243,Data_Long!$A$6:$A$243,F$5,Data_Long!$B$6:$B$243,$A12)) -> 3061.4555 | G12: =IF(COUNTIFS(Data_Long!$A$6:$A$243,G$5,Data_Long!$B$6:$B$243,$A12)=0,"",SUMIFS(Data_Long!$D$6:$D$243,Data_Long!$A$6:$A$243,G$5,Data_Long!$B$6:$B$243,$A12)) -> 2575.4372 | H12: =IF(COUNTIFS(Data_Long!$A$6:$A$243,H$5,Data_Long!$B$6:$B$243,$A12)=0,"",SUMIFS(Data_Long!$D$6:$D$243,Data_Long!$A$6:$A$243,H$5,Data_Long!$B$6:$B$243,$A12)) -> 1006.7913 | I12: =IF(COUNTIFS(Data_Long!$A$6:$A$243,I$5,Data_Long!$B$6:$B$243,$A12)=0,"",SUMIFS(Data_Long!$D$6:$D$243,Data_Long!$A$6:$A$243,I$5,Data_Long!$B$6:$B$243,$A12)) -> -593.50733 | J12: =IF(COUNTIFS(Data_Long!$A$6:$A$243,J$5,Data_Long!$B$6:$B$243,$A12)=0,"",SUMIFS(Data_Long!$D$6:$D$243,Data_Long!$A$6:$A$243,J$5,Data_Long!$B$6:$B$243,$A12)) -> 1348.185 | K12: S025, SQL derived
A13: A01 | B13: Automotive sales revenue | C13: EUR m | D13: =IF(COUNTIFS(Data_Long!$A$6:$A$243,D$5,Data_Long!$B$6:$B$243,$A13)=0,"",SUMIFS(Data_Long!$D$6:$D$243,Data_Long!$A$6:$A$243,D$5,Data_Long!$B$6:$B$243,$A13)) -> 18892 | E13: =IF(COUNTIFS(Data_Long!$A$6:$A$243,E$5,Data_Long!$B$6:$B$243,$A13)=0,"",SUMIFS(Data_Long!$D$6:$D$243,Data_Long!$A$6:$A$243,E$5,Data_Long!$B$6:$B$243,$A13)) -> 18457 | F13: =IF(COUNTIFS(Data_Long!$A$6:$A$243,F$5,Data_Long!$B$6:$B$243,$A13)=0,"",SUMIFS(Data_Long!$D$6:$D$243,Data_Long!$A$6:$A$243,F$5,Data_Long!$B$6:$B$243,$A13)) -> 17695 | G13: =IF(COUNTIFS(Data_Long!$A$6:$A$243,G$5,Data_Long!$B$6:$B$243,$A13)=0,"",SUMIFS(Data_Long!$D$6:$D$243,Data_Long!$A$6:$A$243,G$5,Data_Long!$B$6:$B$243,$A13)) -> 18743 | H13: =IF(COUNTIFS(Data_Long!$A$6:$A$243,H$5,Data_Long!$B$6:$B$243,$A13)=0,"",SUMIFS(Data_Long!$D$6:$D$243,Data_Long!$A$6:$A$243,H$5,Data_Long!$B$6:$B$243,$A13)) -> 16138 | I13: =IF(COUNTIFS(Data_Long!$A$6:$A$243,I$5,Data_Long!$B$6:$B$243,$A13)=0,"",SUMIFS(Data_Long!$D$6:$D$243,Data_Long!$A$6:$A$243,I$5,Data_Long!$B$6:$B$243,$A13)) -> 16047 | J13: =IF(COUNTIFS(Data_Long!$A$6:$A$243,J$5,Data_Long!$B$6:$B$243,$A13)=0,"",SUMIFS(Data_Long!$D$6:$D$243,Data_Long!$A$6:$A$243,J$5,Data_Long!$B$6:$B$243,$A13)) -> 15158 | K13: S002, S006, S010, S017, SQL derived
A14: A02 | B14: Automotive operating profit | C14: EUR m | D14: =IF(COUNTIFS(Data_Long!$A$6:$A$243,D$5,Data_Long!$B$6:$B$243,$A14)=0,"",SUMIFS(Data_Long!$D$6:$D$243,Data_Long!$A$6:$A$243,D$5,Data_Long!$B$6:$B$243,$A14)) -> 3653 | E14: =IF(COUNTIFS(Data_Long!$A$6:$A$243,E$5,Data_Long!$B$6:$B$243,$A14)=0,"",SUMIFS(Data_Long!$D$6:$D$243,Data_Long!$A$6:$A$243,E$5,Data_Long!$B$6:$B$243,$A14)) -> 3285 | F14: =IF(COUNTIFS(Data_Long!$A$6:$A$243,F$5,Data_Long!$B$6:$B$243,$A14)=0,"",SUMIFS(Data_Long!$D$6:$D$243,Data_Long!$A$6:$A$243,F$5,Data_Long!$B$6:$B$243,$A14)) -> 2904 | G14: =IF(COUNTIFS(Data_Long!$A$6:$A$243,G$5,Data_Long!$B$6:$B$243,$A14)=0,"",SUMIFS(Data_Long!$D$6:$D$243,Data_Long!$A$6:$A$243,G$5,Data_Long!$B$6:$B$243,$A14)) -> 2382 | H14: =IF(COUNTIFS(Data_Long!$A$6:$A$243,H$5,Data_Long!$B$6:$B$243,$A14)=0,"",SUMIFS(Data_Long!$D$6:$D$243,Data_Long!$A$6:$A$243,H$5,Data_Long!$B$6:$B$243,$A14)) -> 832 | I14: =IF(COUNTIFS(Data_Long!$A$6:$A$243,I$5,Data_Long!$B$6:$B$243,$A14)=0,"",SUMIFS(Data_Long!$D$6:$D$243,Data_Long!$A$6:$A$243,I$5,Data_Long!$B$6:$B$243,$A14)) -> -742 | J14: =IF(COUNTIFS(Data_Long!$A$6:$A$243,J$5,Data_Long!$B$6:$B$243,$A14)=0,"",SUMIFS(Data_Long!$D$6:$D$243,Data_Long!$A$6:$A$243,J$5,Data_Long!$B$6:$B$243,$A14)) -> 1208 | K14: S002, S006, S010, S017, SQL derived
A15: A03 | B15: Automotive EBITDA | C15: EUR m | D15: =IF(COUNTIFS(Data_Long!$A$6:$A$243,D$5,Data_Long!$B$6:$B$243,$A15)=0,"",SUMIFS(Data_Long!$D$6:$D$243,Data_Long!$A$6:$A$243,D$5,Data_Long!$B$6:$B$243,$A15)) -> 4829 | E15: =IF(COUNTIFS(Data_Long!$A$6:$A$243,E$5,Data_Long!$B$6:$B$243,$A15)=0,"",SUMIFS(Data_Long!$D$6:$D$243,Data_Long!$A$6:$A$243,E$5,Data_Long!$B$6:$B$243,$A15)) -> 4765 | F15: =IF(COUNTIFS(Data_Long!$A$6:$A$243,F$5,Data_Long!$B$6:$B$243,$A15)=0,"",SUMIFS(Data_Long!$D$6:$D$243,Data_Long!$A$6:$A$243,F$5,Data_Long!$B$6:$B$243,$A15)) -> 4268 | G15: =IF(COUNTIFS(Data_Long!$A$6:$A$243,G$5,Data_Long!$B$6:$B$243,$A15)=0,"",SUMIFS(Data_Long!$D$6:$D$243,Data_Long!$A$6:$A$243,G$5,Data_Long!$B$6:$B$243,$A15)) -> 4003 | H15: =IF(COUNTIFS(Data_Long!$A$6:$A$243,H$5,Data_Long!$B$6:$B$243,$A15)=0,"",SUMIFS(Data_Long!$D$6:$D$243,Data_Long!$A$6:$A$243,H$5,Data_Long!$B$6:$B$243,$A15)) -> 2588 | I15: =IF(COUNTIFS(Data_Long!$A$6:$A$243,I$5,Data_Long!$B$6:$B$243,$A15)=0,"",SUMIFS(Data_Long!$D$6:$D$243,Data_Long!$A$6:$A$243,I$5,Data_Long!$B$6:$B$243,$A15)) -> 1694 | J15: =IF(COUNTIFS(Data_Long!$A$6:$A$243,J$5,Data_Long!$B$6:$B$243,$A15)=0,"",SUMIFS(Data_Long!$D$6:$D$243,Data_Long!$A$6:$A$243,J$5,Data_Long!$B$6:$B$243,$A15)) -> 2767 | K15: S002, S006, S010, S017, SQL derived
A16: A04 | B16: Automotive EBITDA margin (published) | C16: % | D16: =IF(COUNTIFS(Data_Long!$A$6:$A$243,D$5,Data_Long!$B$6:$B$243,$A16)=0,"",SUMIFS(Data_Long!$D$6:$D$243,Data_Long!$A$6:$A$243,D$5,Data_Long!$B$6:$B$243,$A16)) -> 25.6 | E16: =IF(COUNTIFS(Data_Long!$A$6:$A$243,E$5,Data_Long!$B$6:$B$243,$A16)=0,"",SUMIFS(Data_Long!$D$6:$D$243,Data_Long!$A$6:$A$243,E$5,Data_Long!$B$6:$B$243,$A16)) | F16: =IF(COUNTIFS(Data_Long!$A$6:$A$243,F$5,Data_Long!$B$6:$B$243,$A16)=0,"",SUMIFS(Data_Long!$D$6:$D$243,Data_Long!$A$6:$A$243,F$5,Data_Long!$B$6:$B$243,$A16)) -> 24.1 | G16: =IF(COUNTIFS(Data_Long!$A$6:$A$243,G$5,Data_Long!$B$6:$B$243,$A16)=0,"",SUMIFS(Data_Long!$D$6:$D$243,Data_Long!$A$6:$A$243,G$5,Data_Long!$B$6:$B$243,$A16)) | H16: =IF(COUNTIFS(Data_Long!$A$6:$A$243,H$5,Data_Long!$B$6:$B$243,$A16)=0,"",SUMIFS(Data_Long!$D$6:$D$243,Data_Long!$A$6:$A$243,H$5,Data_Long!$B$6:$B$243,$A16)) -> 16 | I16: =IF(COUNTIFS(Data_Long!$A$6:$A$243,I$5,Data_Long!$B$6:$B$243,$A16)=0,"",SUMIFS(Data_Long!$D$6:$D$243,Data_Long!$A$6:$A$243,I$5,Data_Long!$B$6:$B$243,$A16)) | J16: =IF(COUNTIFS(Data_Long!$A$6:$A$243,J$5,Data_Long!$B$6:$B$243,$A16)=0,"",SUMIFS(Data_Long!$D$6:$D$243,Data_Long!$A$6:$A$243,J$5,Data_Long!$B$6:$B$243,$A16)) -> 18.3 | K16: S002, S006, S010, S017
A17: A05 | B17: Automotive R&D costs (total) | C17: EUR m | D17: =IF(COUNTIFS(Data_Long!$A$6:$A$243,D$5,Data_Long!$B$6:$B$243,$A17)=0,"",SUMIFS(Data_Long!$D$6:$D$243,Data_Long!$A$6:$A$243,D$5,Data_Long!$B$6:$B$243,$A17)) -> 1545 | E17: =IF(COUNTIFS(Data_Long!$A$6:$A$243,E$5,Data_Long!$B$6:$B$243,$A17)=0,"",SUMIFS(Data_Long!$D$6:$D$243,Data_Long!$A$6:$A$243,E$5,Data_Long!$B$6:$B$243,$A17)) -> 1289 | F17: =IF(COUNTIFS(Data_Long!$A$6:$A$243,F$5,Data_Long!$B$6:$B$243,$A17)=0,"",SUMIFS(Data_Long!$D$6:$D$243,Data_Long!$A$6:$A$243,F$5,Data_Long!$B$6:$B$243,$A17)) -> 1665 | G17: =IF(COUNTIFS(Data_Long!$A$6:$A$243,G$5,Data_Long!$B$6:$B$243,$A17)=0,"",SUMIFS(Data_Long!$D$6:$D$243,Data_Long!$A$6:$A$243,G$5,Data_Long!$B$6:$B$243,$A17)) -> 863 | H17: =IF(COUNTIFS(Data_Long!$A$6:$A$243,H$5,Data_Long!$B$6:$B$243,$A17)=0,"",SUMIFS(Data_Long!$D$6:$D$243,Data_Long!$A$6:$A$243,H$5,Data_Long!$B$6:$B$243,$A17)) -> 1264 | I17: =IF(COUNTIFS(Data_Long!$A$6:$A$243,I$5,Data_Long!$B$6:$B$243,$A17)=0,"",SUMIFS(Data_Long!$D$6:$D$243,Data_Long!$A$6:$A$243,I$5,Data_Long!$B$6:$B$243,$A17)) -> 1028 | J17: =IF(COUNTIFS(Data_Long!$A$6:$A$243,J$5,Data_Long!$B$6:$B$243,$A17)=0,"",SUMIFS(Data_Long!$D$6:$D$243,Data_Long!$A$6:$A$243,J$5,Data_Long!$B$6:$B$243,$A17)) -> 1116 | K17: S002, S016, SQL derived
... A44: O07 | B44: BEV share (published) | C44: % | D44: =IF(COUNTIFS(Data_Long!$A$6:$A$243,D$5,Data_Long!$B$6:$B$243,$A44)=0,"",SUMIFS(Data_Long!$D$6:$D$243,Data_Long!$A$6:$A$243,D$5,Data_Long!$B$6:$B$243,$A44)) -> 10.8 | E44: =IF(COUNTIFS(Data_Long!$A$6:$A$243,E$5,Data_Long!$B$6:$B$243,$A44)=0,"",SUMIFS(Data_Long!$D$6:$D$243,Data_Long!$A$6:$A$243,E$5,Data_Long!$B$6:$B$243,$A44)) | F44: =IF(COUNTIFS(Data_Long!$A$6:$A$243,F$5,Data_Long!$B$6:$B$243,$A44)=0,"",SUMIFS(Data_Long!$D$6:$D$243,Data_Long!$A$6:$A$243,F$5,Data_Long!$B$6:$B$243,$A44)) -> 5.9 | G44: =IF(COUNTIFS(Data_Long!$A$6:$A$243,G$5,Data_Long!$B$6:$B$243,$A44)=0,"",SUMIFS(Data_Long!$D$6:$D$243,Data_Long!$A$6:$A$243,G$5,Data_Long!$B$6:$B$243,$A44)) | H44: =IF(COUNTIFS(Data_Long!$A$6:$A$243,H$5,Data_Long!$B$6:$B$243,$A44)=0,"",SUMIFS(Data_Long!$D$6:$D$243,Data_Long!$A$6:$A$243,H$5,Data_Long!$B$6:$B$243,$A44)) -> 23.5 | I44: =IF(COUNTIFS(Data_Long!$A$6:$A$243,I$5,Data_Long!$B$6:$B$243,$A44)=0,"",SUMIFS(Data_Long!$D$6:$D$243,Data_Long!$A$6:$A$243,I$5,Data_Long!$B$6:$B$243,$A44)) | J44: =IF(COUNTIFS(Data_Long!$A$6:$A$243,J$5,Data_Long!$B$6:$B$243,$A44)=0,"",SUMIFS(Data_Long!$D$6:$D$243,Data_Long!$A$6:$A$243,J$5,Data_Long!$B$6:$B$243,$A44)) -> 19.4 | K44: S006, S010, S017
A46: Label grid: FACT = published by Porsche; DERIVED = calculated in SQL from published values (see Data_Long source_ref).
A47: var_id | B47: variable | D47: 2023-H1 | E47: 2023-H2 | F47: 2024-H1 | G47: 2024-H2 | H47: 2025-H1 | I47: 2025-H2 | J47: 2026-H1
A48: G01 | B48: Group sales revenue | D48: =IF(COUNTIFS(Data_Long!$A$6:$A$243,D$5,Data_Long!$B$6:$B$243,$A48)=0,"not published",IF(COUNTIFS(Data_Long!$A$6:$A$243,D$5,Data_Long!$B$6:$B$243,$A48,Data_Long!$F$6:$F$243,"DERIVED")>0,"DERIVED","FACT")) -> FACT | E48: =IF(COUNTIFS(Data_Long!$A$6:$A$243,E$5,Data_Long!$B$6:$B$243,$A48)=0,"not published",IF(COUNTIFS(Data_Long!$A$6:$A$243,E$5,Data_Long!$B$6:$B$243,$A48,Data_Long!$F$6:$F$243,"DERIVED")>0,"DERIVED","FACT")) -> DERIVED | F48: =IF(COUNTIFS(Data_Long!$A$6:$A$243,F$5,Data_Long!$B$6:$B$243,$A48)=0,"not published",IF(COUNTIFS(Data_Long!$A$6:$A$243,F$5,Data_Long!$B$6:$B$243,$A48,Data_Long!$F$6:$F$243,"DERIVED")>0,"DERIVED","FACT")) -> FACT | G48: =IF(COUNTIFS(Data_Long!$A$6:$A$243,G$5,Data_Long!$B$6:$B$243,$A48)=0,"not published",IF(COUNTIFS(Data_Long!$A$6:$A$243,G$5,Data_Long!$B$6:$B$243,$A48,Data_Long!$F$6:$F$243,"DERIVED")>0,"DERIVED","FACT")) -> DERIVED | H48: =IF(COUNTIFS(Data_Long!$A$6:$A$243,H$5,Data_Long!$B$6:$B$243,$A48)=0,"not published",IF(COUNTIFS(Data_Long!$A$6:$A$243,H$5,Data_Long!$B$6:$B$243,$A48,Data_Long!$F$6:$F$243,"DERIVED")>0,"DERIVED","FACT")) -> FACT | I48: =IF(COUNTIFS(Data_Long!$A$6:$A$243,I$5,Data_Long!$B$6:$B$243,$A48)=0,"not published",IF(COUNTIFS(Data_Long!$A$6:$A$243,I$5,Data_Long!$B$6:$B$243,$A48,Data_Long!$F$6:$F$243,"DERIVED")>0,"DERIVED","FACT")) -> DERIVED | J48: =IF(COUNTIFS(Data_Long!$A$6:$A$243,J$5,Data_Long!$B$6:$B$243,$A48)=0,"not published",IF(COUNTIFS(Data_Long!$A$6:$A$243,J$5,Data_Long!$B$6:$B$243,$A48,Data_Long!$F$6:$F$243,"DERIVED")>0,"DERIVED","FACT")) -> FACT
A49: G02 | B49: Cost of sales | D49: =IF(COUNTIFS(Data_Long!$A$6:$A$243,D$5,Data_Long!$B$6:$B$243,$A49)=0,"not published",IF(COUNTIFS(Data_Long!$A$6:$A$243,D$5,Data_Long!$B$6:$B$243,$A49,Data_Long!$F$6:$F$243,"DERIVED")>0,"DERIVED","FACT")) -> FACT | E49: =IF(COUNTIFS(Data_Long!$A$6:$A$243,E$5,Data_Long!$B$6:$B$243,$A49)=0,"not published",IF(COUNTIFS(Data_Long!$A$6:$A$243,E$5,Data_Long!$B$6:$B$243,$A49,Data_Long!$F$6:$F$243,"DERIVED")>0,"DERIVED","FACT")) -> DERIVED | F49: =IF(COUNTIFS(Data_Long!$A$6:$A$243,F$5,Data_Long!$B$6:$B$243,$A49)=0,"not published",IF(COUNTIFS(Data_Long!$A$6:$A$243,F$5,Data_Long!$B$6:$B$243,$A49,Data_Long!$F$6:$F$243,"DERIVED")>0,"DERIVED","FACT")) -> FACT | G49: =IF(COUNTIFS(Data_Long!$A$6:$A$243,G$5,Data_Long!$B$6:$B$243,$A49)=0,"not published",IF(COUNTIFS(Data_Long!$A$6:$A$243,G$5,Data_Long!$B$6:$B$243,$A49,Data_Long!$F$6:$F$243,"DERIVED")>0,"DERIVED","FACT")) -> DERIVED | H49: =IF(COUNTIFS(Data_Long!$A$6:$A$243,H$5,Data_Long!$B$6:$B$243,$A49)=0,"not published",IF(COUNTIFS(Data_Long!$A$6:$A$243,H$5,Data_Long!$B$6:$B$243,$A49,Data_Long!$F$6:$F$243,"DERIVED")>0,"DERIVED","FACT")) -> FACT | I49: =IF(COUNTIFS(Data_Long!$A$6:$A$243,I$5,Data_Long!$B$6:$B$243,$A49)=0,"not published",IF(COUNTIFS(Data_Long!$A$6:$A$243,I$5,Data_Long!$B$6:$B$243,$A49,Data_Long!$F$6:$F$243,"DERIVED")>0,"DERIVED","FACT")) -> DERIVED | J49: =IF(COUNTIFS(Data_Long!$A$6:$A$243,J$5,Data_Long!$B$6:$B$243,$A49)=0,"not published",IF(COUNTIFS(Data_Long!$A$6:$A$243,J$5,Data_Long!$B$6:$B$243,$A49,Data_Long!$F$6:$F$243,"DERIVED")>0,"DERIVED","FACT")) -> FACT
A50: G03 | B50: Gross profit | D50: =IF(COUNTIFS(Data_Long!$A$6:$A$243,D$5,Data_Long!$B$6:$B$243,$A50)=0,"not published",IF(COUNTIFS(Data_Long!$A$6:$A$243,D$5,Data_Long!$B$6:$B$243,$A50,Data_Long!$F$6:$F$243,"DERIVED")>0,"DERIVED","FACT")) -> FACT | E50: =IF(COUNTIFS(Data_Long!$A$6:$A$243,E$5,Data_Long!$B$6:$B$243,$A50)=0,"not published",IF(COUNTIFS(Data_Long!$A$6:$A$243,E$5,Data_Long!$B$6:$B$243,$A50,Data_Long!$F$6:$F$243,"DERIVED")>0,"DERIVED","FACT")) -> DERIVED | F50: =IF(COUNTIFS(Data_Long!$A$6:$A$243,F$5,Data_Long!$B$6:$B$243,$A50)=0,"not published",IF(COUNTIFS(Data_Long!$A$6:$A$243,F$5,Data_Long!$B$6:$B$243,$A50,Data_Long!$F$6:$F$243,"DERIVED")>0,"DERIVED","FACT")) -> FACT | G50: =IF(COUNTIFS(Data_Long!$A$6:$A$243,G$5,Data_Long!$B$6:$B$243,$A50)=0,"not published",IF(COUNTIFS(Data_Long!$A$6:$A$243,G$5,Data_Long!$B$6:$B$243,$A50,Data_Long!$F$6:$F$243,"DERIVED")>0,"DERIVED","FACT")) -> DERIVED | H50: =IF(COUNTIFS(Data_Long!$A$6:$A$243,H$5,Data_Long!$B$6:$B$243,$A50)=0,"not published",IF(COUNTIFS(Data_Long!$A$6:$A$243,H$5,Data_Long!$B$6:$B$243,$A50,Data_Long!$F$6:$F$243,"DERIVED")>0,"DERIVED","FACT")) -> FACT | I50: =IF(COUNTIFS(Data_Long!$A$6:$A$243,I$5,Data_Long!$B$6:$B$243,$A50)=0,"not published",IF(COUNTIFS(Data_Long!$A$6:$A$243,I$5,Data_Long!$B$6:$B$243,$A50,Data_Long!$F$6:$F$243,"DERIVED")>0,"DERIVED","FACT")) -> DERIVED | J50: =IF(COUNTIFS(Data_Long!$A$6:$A$243,J$5,Data_Long!$B$6:$B$243,$A50)=0,"not published",IF(COUNTIFS(Data_Long!$A$6:$A$243,J$5,Data_Long!$B$6:$B$243,$A50,Data_Long!$F$6:$F$243,"DERIVED")>0,"DERIVED","FACT")) -> FACT
A51: G04 | B51: Distribution expenses | D51: =IF(COUNTIFS(Data_Long!$A$6:$A$243,D$5,Data_Long!$B$6:$B$243,$A51)=0,"not published",IF(COUNTIFS(Data_Long!$A$6:$A$243,D$5,Data_Long!$B$6:$B$243,$A51,Data_Long!$F$6:$F$243,"DERIVED")>0,"DERIVED","FACT")) -> FACT | E51: =IF(COUNTIFS(Data_Long!$A$6:$A$243,E$5,Data_Long!$B$6:$B$243,$A51)=0,"not published",IF(COUNTIFS(Data_Long!$A$6:$A$243,E$5,Data_Long!$B$6:$B$243,$A51,Data_Long!$F$6:$F$243,"DERIVED")>0,"DERIVED","FACT")) -> DERIVED | F51: =IF(COUNTIFS(Data_Long!$A$6:$A$243,F$5,Data_Long!$B$6:$B$243,$A51)=0,"not published",IF(COUNTIFS(Data_Long!$A$6:$A$243,F$5,Data_Long!$B$6:$B$243,$A51,Data_Long!$F$6:$F$243,"DERIVED")>0,"DERIVED","FACT")) -> FACT | G51: =IF(COUNTIFS(Data_Long!$A$6:$A$243,G$5,Data_Long!$B$6:$B$243,$A51)=0,"not published",IF(COUNTIFS(Data_Long!$A$6:$A$243,G$5,Data_Long!$B$6:$B$243,$A51,Data_Long!$F$6:$F$243,"DERIVED")>0,"DERIVED","FACT")) -> DERIVED | H51: =IF(COUNTIFS(Data_Long!$A$6:$A$243,H$5,Data_Long!$B$6:$B$243,$A51)=0,"not published",IF(COUNTIFS(Data_Long!$A$6:$A$243,H$5,Data_Long!$B$6:$B$243,$A51,Data_Long!$F$6:$F$243,"DERIVED")>0,"DERIVED","FACT")) -> FACT | I51: =IF(COUNTIFS(Data_Long!$A$6:$A$243,I$5,Data_Long!$B$6:$B$243,$A51)=0,"not published",IF(COUNTIFS(Data_Long!$A$6:$A$243,I$5,Data_Long!$B$6:$B$243,$A51,Data_Long!$F$6:$F$243,"DERIVED")>0,"DERIVED","FACT")) -> DERIVED | J51: =IF(COUNTIFS(Data_Long!$A$6:$A$243,J$5,Data_Long!$B$6:$B$243,$A51)=0,"not published",IF(COUNTIFS(Data_Long!$A$6:$A$243,J$5,Data_Long!$B$6:$B$243,$A51,Data_Long!$F$6:$F$243,"DERIVED")>0,"DERIVED","FACT")) -> FACT
A52: G05 | B52: Administrative expenses | D52: =IF(COUNTIFS(Data_Long!$A$6:$A$243,D$5,Data_Long!$B$6:$B$243,$A52)=0,"not published",IF(COUNTIFS(Data_Long!$A$6:$A$243,D$5,Data_Long!$B$6:$B$243,$A52,Data_Long!$F$6:$F$243,"DERIVED")>0,"DERIVED","FACT")) -> FACT | E52: =IF(COUNTIFS(Data_Long!$A$6:$A$243,E$5,Data_Long!$B$6:$B$243,$A52)=0,"not published",IF(COUNTIFS(Data_Long!$A$6:$A$243,E$5,Data_Long!$B$6:$B$243,$A52,Data_Long!$F$6:$F$243,"DERIVED")>0,"DERIVED","FACT")) -> DERIVED | F52: =IF(COUNTIFS(Data_Long!$A$6:$A$243,F$5,Data_Long!$B$6:$B$243,$A52)=0,"not published",IF(COUNTIFS(Data_Long!$A$6:$A$243,F$5,Data_Long!$B$6:$B$243,$A52,Data_Long!$F$6:$F$243,"DERIVED")>0,"DERIVED","FACT")) -> FACT | G52: =IF(COUNTIFS(Data_Long!$A$6:$A$243,G$5,Data_Long!$B$6:$B$243,$A52)=0,"not published",IF(COUNTIFS(Data_Long!$A$6:$A$243,G$5,Data_Long!$B$6:$B$243,$A52,Data_Long!$F$6:$F$243,"DERIVED")>0,"DERIVED","FACT")) -> DERIVED | H52: =IF(COUNTIFS(Data_Long!$A$6:$A$243,H$5,Data_Long!$B$6:$B$243,$A52)=0,"not published",IF(COUNTIFS(Data_Long!$A$6:$A$243,H$5,Data_Long!$B$6:$B$243,$A52,Data_Long!$F$6:$F$243,"DERIVED")>0,"DERIVED","FACT")) -> FACT | I52: =IF(COUNTIFS(Data_Long!$A$6:$A$243,I$5,Data_Long!$B$6:$B$243,$A52)=0,"not published",IF(COUNTIFS(Data_Long!$A$6:$A$243,I$5,Data_Long!$B$6:$B$243,$A52,Data_Long!$F$6:$F$243,"DERIVED")>0,"DERIVED","FACT")) -> DERIVED | J52: =IF(COUNTIFS(Data_Long!$A$6:$A$243,J$5,Data_Long!$B$6:$B$243,$A52)=0,"not published",IF(COUNTIFS(Data_Long!$A$6:$A$243,J$5,Data_Long!$B$6:$B$243,$A52,Data_Long!$F$6:$F$243,"DERIVED")>0,"DERIVED","FACT")) -> FACT
A53: G06 | B53: Net other operating result | D53: =IF(COUNTIFS(Data_Long!$A$6:$A$243,D$5,Data_Long!$B$6:$B$243,$A53)=0,"not published",IF(COUNTIFS(Data_Long!$A$6:$A$243,D$5,Data_Long!$B$6:$B$243,$A53,Data_Long!$F$6:$F$243,"DERIVED")>0,"DERIVED","FACT")) -> FACT | E53: =IF(COUNTIFS(Data_Long!$A$6:$A$243,E$5,Data_Long!$B$6:$B$243,$A53)=0,"not published",IF(COUNTIFS(Data_Long!$A$6:$A$243,E$5,Data_Long!$B$6:$B$243,$A53,Data_Long!$F$6:$F$243,"DERIVED")>0,"DERIVED","FACT")) -> DERIVED | F53: =IF(COUNTIFS(Data_Long!$A$6:$A$243,F$5,Data_Long!$B$6:$B$243,$A53)=0,"not published",IF(COUNTIFS(Data_Long!$A$6:$A$243,F$5,Data_Long!$B$6:$B$243,$A53,Data_Long!$F$6:$F$243,"DERIVED")>0,"DERIVED","FACT")) -> FACT | G53: =IF(COUNTIFS(Data_Long!$A$6:$A$243,G$5,Data_Long!$B$6:$B$243,$A53)=0,"not published",IF(COUNTIFS(Data_Long!$A$6:$A$243,G$5,Data_Long!$B$6:$B$243,$A53,Data_Long!$F$6:$F$243,"DERIVED")>0,"DERIVED","FACT")) -> DERIVED | H53: =IF(COUNTIFS(Data_Long!$A$6:$A$243,H$5,Data_Long!$B$6:$B$243,$A53)=0,"not published",IF(COUNTIFS(Data_Long!$A$6:$A$243,H$5,Data_Long!$B$6:$B$243,$A53,Data_Long!$F$6:$F$243,"DERIVED")>0,"DERIVED","FACT")) -> FACT | I53: =IF(COUNTIFS(Data_Long!$A$6:$A$243,I$5,Data_Long!$B$6:$B$243,$A53)=0,"not published",IF(COUNTIFS(Data_Long!$A$6:$A$243,I$5,Data_Long!$B$6:$B$243,$A53,Data_Long!$F$6:$F$243,"DERIVED")>0,"DERIVED","FACT")) -> DERIVED | J53: =IF(COUNTIFS(Data_Long!$A$6:$A$243,J$5,Data_Long!$B$6:$B$243,$A53)=0,"not published",IF(COUNTIFS(Data_Long!$A$6:$A$243,J$5,Data_Long!$B$6:$B$243,$A53,Data_Long!$F$6:$F$243,"DERIVED")>0,"DERIVED","FACT")) -> FACT
A54: G07 | B54: Operating profit (EBIT), group | D54: =IF(COUNTIFS(Data_Long!$A$6:$A$243,D$5,Data_Long!$B$6:$B$243,$A54)=0,"not published",IF(COUNTIFS(Data_Long!$A$6:$A$243,D$5,Data_Long!$B$6:$B$243,$A54,Data_Long!$F$6:$F$243,"DERIVED")>0,"DERIVED","FACT")) -> FACT | E54: =IF(COUNTIFS(Data_Long!$A$6:$A$243,E$5,Data_Long!$B$6:$B$243,$A54)=0,"not published",IF(COUNTIFS(Data_Long!$A$6:$A$243,E$5,Data_Long!$B$6:$B$243,$A54,Data_Long!$F$6:$F$243,"DERIVED")>0,"DERIVED","FACT")) -> DERIVED | F54: =IF(COUNTIFS(Data_Long!$A$6:$A$243,F$5,Data_Long!$B$6:$B$243,$A54)=0,"not published",IF(COUNTIFS(Data_Long!$A$6:$A$243,F$5,Data_Long!$B$6:$B$243,$A54,Data_Long!$F$6:$F$243,"DERIVED")>0,"DERIVED","FACT")) -> FACT | G54: =IF(COUNTIFS(Data_Long!$A$6:$A$243,G$5,Data_Long!$B$6:$B$243,$A54)=0,"not published",IF(COUNTIFS(Data_Long!$A$6:$A$243,G$5,Data_Long!$B$6:$B$243,$A54,Data_Long!$F$6:$F$243,"DERIVED")>0,"DERIVED","FACT")) -> DERIVED | H54: =IF(COUNTIFS(Data_Long!$A$6:$A$243,H$5,Data_Long!$B$6:$B$243,$A54)=0,"not published",IF(COUNTIFS(Data_Long!$A$6:$A$243,H$5,Data_Long!$B$6:$B$243,$A54,Data_Long!$F$6:$F$243,"DERIVED")>0,"DERIVED","FACT")) -> FACT | I54: =IF(COUNTIFS(Data_Long!$A$6:$A$243,I$5,Data_Long!$B$6:$B$243,$A54)=0,"not published",IF(COUNTIFS(Data_Long!$A$6:$A$243,I$5,Data_Long!$B$6:$B$243,$A54,Data_Long!$F$6:$F$243,"DERIVED")>0,"DERIVED","FACT")) -> DERIVED | J54: =IF(COUNTIFS(Data_Long!$A$6:$A$243,J$5,Data_Long!$B$6:$B$243,$A54)=0,"not published",IF(COUNTIFS(Data_Long!$A$6:$A$243,J$5,Data_Long!$B$6:$B$243,$A54,Data_Long!$F$6:$F$243,"DERIVED")>0,"DERIVED","FACT")) -> FACT
A55: A01 | B55: Automotive sales revenue | D55: =IF(COUNTIFS(Data_Long!$A$6:$A$243,D$5,Data_Long!$B$6:$B$243,$A55)=0,"not published",IF(COUNTIFS(Data_Long!$A$6:$A$243,D$5,Data_Long!$B$6:$B$243,$A55,Data_Long!$F$6:$F$243,"DERIVED")>0,"DERIVED","FACT")) -> FACT | E55: =IF(COUNTIFS(Data_Long!$A$6:$A$243,E$5,Data_Long!$B$6:$B$243,$A55)=0,"not published",IF(COUNTIFS(Data_Long!$A$6:$A$243,E$5,Data_Long!$B$6:$B$243,$A55,Data_Long!$F$6:$F$243,"DERIVED")>0,"DERIVED","FACT")) -> DERIVED | F55: =IF(COUNTIFS(Data_Long!$A$6:$A$243,F$5,Data_Long!$B$6:$B$243,$A55)=0,"not published",IF(COUNTIFS(Data_Long!$A$6:$A$243,F$5,Data_Long!$B$6:$B$243,$A55,Data_Long!$F$6:$F$243,"DERIVED")>0,"DERIVED","FACT")) -> FACT | G55: =IF(COUNTIFS(Data_Long!$A$6:$A$243,G$5,Data_Long!$B$6:$B$243,$A55)=0,"not published",IF(COUNTIFS(Data_Long!$A$6:$A$243,G$5,Data_Long!$B$6:$B$243,$A55,Data_Long!$F$6:$F$243,"DERIVED")>0,"DERIVED","FACT")) -> DERIVED | H55: =IF(COUNTIFS(Data_Long!$A$6:$A$243,H$5,Data_Long!$B$6:$B$243,$A55)=0,"not published",IF(COUNTIFS(Data_Long!$A$6:$A$243,H$5,Data_Long!$B$6:$B$243,$A55,Data_Long!$F$6:$F$243,"DERIVED")>0,"DERIVED","FACT")) -> FACT | I55: =IF(COUNTIFS(Data_Long!$A$6:$A$243,I$5,Data_Long!$B$6:$B$243,$A55)=0,"not published",IF(COUNTIFS(Data_Long!$A$6:$A$243,I$5,Data_Long!$B$6:$B$243,$A55,Data_Long!$F$6:$F$243,"DERIVED")>0,"DERIVED","FACT")) -> DERIVED | J55: =IF(COUNTIFS(Data_Long!$A$6:$A$243,J$5,Data_Long!$B$6:$B$243,$A55)=0,"not published",IF(COUNTIFS(Data_Long!$A$6:$A$243,J$5,Data_Long!$B$6:$B$243,$A55,Data_Long!$F$6:$F$243,"DERIVED")>0,"DERIVED","FACT")) -> FACT
A56: A02 | B56: Automotive operating profit | D56: =IF(COUNTIFS(Data_Long!$A$6:$A$243,D$5,Data_Long!$B$6:$B$243,$A56)=0,"not published",IF(COUNTIFS(Data_Long!$A$6:$A$243,D$5,Data_Long!$B$6:$B$243,$A56,Data_Long!$F$6:$F$243,"DERIVED")>0,"DERIVED","FACT")) -> FACT | E56: =IF(COUNTIFS(Data_Long!$A$6:$A$243,E$5,Data_Long!$B$6:$B$243,$A56)=0,"not published",IF(COUNTIFS(Data_Long!$A$6:$A$243,E$5,Data_Long!$B$6:$B$243,$A56,Data_Long!$F$6:$F$243,"DERIVED")>0,"DERIVED","FACT")) -> DERIVED | F56: =IF(COUNTIFS(Data_Long!$A$6:$A$243,F$5,Data_Long!$B$6:$B$243,$A56)=0,"not published",IF(COUNTIFS(Data_Long!$A$6:$A$243,F$5,Data_Long!$B$6:$B$243,$A56,Data_Long!$F$6:$F$243,"DERIVED")>0,"DERIVED","FACT")) -> FACT | G56: =IF(COUNTIFS(Data_Long!$A$6:$A$243,G$5,Data_Long!$B$6:$B$243,$A56)=0,"not published",IF(COUNTIFS(Data_Long!$A$6:$A$243,G$5,Data_Long!$B$6:$B$243,$A56,Data_Long!$F$6:$F$243,"DERIVED")>0,"DERIVED","FACT")) -> DERIVED | H56: =IF(COUNTIFS(Data_Long!$A$6:$A$243,H$5,Data_Long!$B$6:$B$243,$A56)=0,"not published",IF(COUNTIFS(Data_Long!$A$6:$A$243,H$5,Data_Long!$B$6:$B$243,$A56,Data_Long!$F$6:$F$243,"DERIVED")>0,"DERIVED","FACT")) -> FACT | I56: =IF(COUNTIFS(Data_Long!$A$6:$A$243,I$5,Data_Long!$B$6:$B$243,$A56)=0,"not published",IF(COUNTIFS(Data_Long!$A$6:$A$243,I$5,Data_Long!$B$6:$B$243,$A56,Data_Long!$F$6:$F$243,"DERIVED")>0,"DERIVED","FACT")) -> DERIVED | J56: =IF(COUNTIFS(Data_Long!$A$6:$A$243,J$5,Data_Long!$B$6:$B$243,$A56)=0,"not published",IF(COUNTIFS(Data_Long!$A$6:$A$243,J$5,Data_Long!$B$6:$B$243,$A56,Data_Long!$F$6:$F$243,"DERIVED")>0,"DERIVED","FACT")) -> FACT
A57: A03 | B57: Automotive EBITDA | D57: =IF(COUNTIFS(Data_Long!$A$6:$A$243,D$5,Data_Long!$B$6:$B$243,$A57)=0,"not published",IF(COUNTIFS(Data_Long!$A$6:$A$243,D$5,Data_Long!$B$6:$B$243,$A57,Data_Long!$F$6:$F$243,"DERIVED")>0,"DERIVED","FACT")) -> FACT | E57: =IF(COUNTIFS(Data_Long!$A$6:$A$243,E$5,Data_Long!$B$6:$B$243,$A57)=0,"not published",IF(COUNTIFS(Data_Long!$A$6:$A$243,E$5,Data_Long!$B$6:$B$243,$A57,Data_Long!$F$6:$F$243,"DERIVED")>0,"DERIVED","FACT")) -> DERIVED | F57: =IF(COUNTIFS(Data_Long!$A$6:$A$243,F$5,Data_Long!$B$6:$B$243,$A57)=0,"not published",IF(COUNTIFS(Data_Long!$A$6:$A$243,F$5,Data_Long!$B$6:$B$243,$A57,Data_Long!$F$6:$F$243,"DERIVED")>0,"DERIVED","FACT")) -> FACT | G57: =IF(COUNTIFS(Data_Long!$A$6:$A$243,G$5,Data_Long!$B$6:$B$243,$A57)=0,"not published",IF(COUNTIFS(Data_Long!$A$6:$A$243,G$5,Data_Long!$B$6:$B$243,$A57,Data_Long!$F$6:$F$243,"DERIVED")>0,"DERIVED","FACT")) -> DERIVED | H57: =IF(COUNTIFS(Data_Long!$A$6:$A$243,H$5,Data_Long!$B$6:$B$243,$A57)=0,"not published",IF(COUNTIFS(Data_Long!$A$6:$A$243,H$5,Data_Long!$B$6:$B$243,$A57,Data_Long!$F$6:$F$243,"DERIVED")>0,"DERIVED","FACT")) -> FACT | I57: =IF(COUNTIFS(Data_Long!$A$6:$A$243,I$5,Data_Long!$B$6:$B$243,$A57)=0,"not published",IF(COUNTIFS(Data_Long!$A$6:$A$243,I$5,Data_Long!$B$6:$B$243,$A57,Data_Long!$F$6:$F$243,"DERIVED")>0,"DERIVED","FACT")) -> DERIVED | J57: =IF(COUNTIFS(Data_Long!$A$6:$A$243,J$5,Data_Long!$B$6:$B$243,$A57)=0,"not published",IF(COUNTIFS(Data_Long!$A$6:$A$243,J$5,Data_Long!$B$6:$B$243,$A57,Data_Long!$F$6:$F$243,"DERIVED")>0,"DERIVED","FACT")) -> FACT
A58: A04 | B58: Automotive EBITDA margin (published) | D58: =IF(COUNTIFS(Data_Long!$A$6:$A$243,D$5,Data_Long!$B$6:$B$243,$A58)=0,"not published",IF(COUNTIFS(Data_Long!$A$6:$A$243,D$5,Data_Long!$B$6:$B$243,$A58,Data_Long!$F$6:$F$243,"DERIVED")>0,"DERIVED","FACT")) -> FACT | E58: =IF(COUNTIFS(Data_Long!$A$6:$A$243,E$5,Data_Long!$B$6:$B$243,$A58)=0,"not published",IF(COUNTIFS(Data_Long!$A$6:$A$243,E$5,Data_Long!$B$6:$B$243,$A58,Data_Long!$F$6:$F$243,"DERIVED")>0,"DERIVED","FACT")) -> not published | F58: =IF(COUNTIFS(Data_Long!$A$6:$A$243,F$5,Data_Long!$B$6:$B$243,$A58)=0,"not published",IF(COUNTIFS(Data_Long!$A$6:$A$243,F$5,Data_Long!$B$6:$B$243,$A58,Data_Long!$F$6:$F$243,"DERIVED")>0,"DERIVED","FACT")) -> FACT | G58: =IF(COUNTIFS(Data_Long!$A$6:$A$243,G$5,Data_Long!$B$6:$B$243,$A58)=0,"not published",IF(COUNTIFS(Data_Long!$A$6:$A$243,G$5,Data_Long!$B$6:$B$243,$A58,Data_Long!$F$6:$F$243,"DERIVED")>0,"DERIVED","FACT")) -> not published | H58: =IF(COUNTIFS(Data_Long!$A$6:$A$243,H$5,Data_Long!$B$6:$B$243,$A58)=0,"not published",IF(COUNTIFS(Data_Long!$A$6:$A$243,H$5,Data_Long!$B$6:$B$243,$A58,Data_Long!$F$6:$F$243,"DERIVED")>0,"DERIVED","FACT")) -> FACT | I58: =IF(COUNTIFS(Data_Long!$A$6:$A$243,I$5,Data_Long!$B$6:$B$243,$A58)=0,"not published",IF(COUNTIFS(Data_Long!$A$6:$A$243,I$5,Data_Long!$B$6:$B$243,$A58,Data_Long!$F$6:$F$243,"DERIVED")>0,"DERIVED","FACT")) -> not published | J58: =IF(COUNTIFS(Data_Long!$A$6:$A$243,J$5,Data_Long!$B$6:$B$243,$A58)=0,"not published",IF(COUNTIFS(Data_Long!$A$6:$A$243,J$5,Data_Long!$B$6:$B$243,$A58,Data_Long!$F$6:$F$243,"DERIVED")>0,"DERIVED","FACT")) -> FACT
A59: A05 | B59: Automotive R&D costs (total) | D59: =IF(COUNTIFS(Data_Long!$A$6:$A$243,D$5,Data_Long!$B$6:$B$243,$A59)=0,"not published",IF(COUNTIFS(Data_Long!$A$6:$A$243,D$5,Data_Long!$B$6:$B$243,$A59,Data_Long!$F$6:$F$243,"DERIVED")>0,"DERIVED","FACT")) -> FACT | E59: =IF(COUNTIFS(Data_Long!$A$6:$A$243,E$5,Data_Long!$B$6:$B$243,$A59)=0,"not published",IF(COUNTIFS(Data_Long!$A$6:$A$243,E$5,Data_Long!$B$6:$B$243,$A59,Data_Long!$F$6:$F$243,"DERIVED")>0,"DERIVED","FACT")) -> DERIVED | F59: =IF(COUNTIFS(Data_Long!$A$6:$A$243,F$5,Data_Long!$B$6:$B$243,$A59)=0,"not published",IF(COUNTIFS(Data_Long!$A$6:$A$243,F$5,Data_Long!$B$6:$B$243,$A59,Data_Long!$F$6:$F$243,"DERIVED")>0,"DERIVED","FACT")) -> FACT | G59: =IF(COUNTIFS(Data_Long!$A$6:$A$243,G$5,Data_Long!$B$6:$B$243,$A59)=0,"not published",IF(COUNTIFS(Data_Long!$A$6:$A$243,G$5,Data_Long!$B$6:$B$243,$A59,Data_Long!$F$6:$F$243,"DERIVED")>0,"DERIVED","FACT")) -> DERIVED | H59: =IF(COUNTIFS(Data_Long!$A$6:$A$243,H$5,Data_Long!$B$6:$B$243,$A59)=0,"not published",IF(COUNTIFS(Data_Long!$A$6:$A$243,H$5,Data_Long!$B$6:$B$243,$A59,Data_Long!$F$6:$F$243,"DERIVED")>0,"DERIVED","FACT")) -> FACT | I59: =IF(COUNTIFS(Data_Long!$A$6:$A$243,I$5,Data_Long!$B$6:$B$243,$A59)=0,"not published",IF(COUNTIFS(Data_Long!$A$6:$A$243,I$5,Data_Long!$B$6:$B$243,$A59,Data_Long!$F$6:$F$243,"DERIVED")>0,"DERIVED","FACT")) -> DERIVED | J59: =IF(COUNTIFS(Data_Long!$A$6:$A$243,J$5,Data_Long!$B$6:$B$243,$A59)=0,"not published",IF(COUNTIFS(Data_Long!$A$6:$A$243,J$5,Data_Long!$B$6:$B$243,$A59,Data_Long!$F$6:$F$243,"DERIVED")>0,"DERIVED","FACT")) -> FACT
... A86: O07 | B86: BEV share (published) | D86: =IF(COUNTIFS(Data_Long!$A$6:$A$243,D$5,Data_Long!$B$6:$B$243,$A86)=0,"not published",IF(COUNTIFS(Data_Long!$A$6:$A$243,D$5,Data_Long!$B$6:$B$243,$A86,Data_Long!$F$6:$F$243,"DERIVED")>0,"DERIVED","FACT")) -> FACT | E86: =IF(COUNTIFS(Data_Long!$A$6:$A$243,E$5,Data_Long!$B$6:$B$243,$A86)=0,"not published",IF(COUNTIFS(Data_Long!$A$6:$A$243,E$5,Data_Long!$B$6:$B$243,$A86,Data_Long!$F$6:$F$243,"DERIVED")>0,"DERIVED","FACT")) -> not published | F86: =IF(COUNTIFS(Data_Long!$A$6:$A$243,F$5,Data_Long!$B$6:$B$243,$A86)=0,"not published",IF(COUNTIFS(Data_Long!$A$6:$A$243,F$5,Data_Long!$B$6:$B$243,$A86,Data_Long!$F$6:$F$243,"DERIVED")>0,"DERIVED","FACT")) -> FACT | G86: =IF(COUNTIFS(Data_Long!$A$6:$A$243,G$5,Data_Long!$B$6:$B$243,$A86)=0,"not published",IF(COUNTIFS(Data_Long!$A$6:$A$243,G$5,Data_Long!$B$6:$B$243,$A86,Data_Long!$F$6:$F$243,"DERIVED")>0,"DERIVED","FACT")) -> not published | H86: =IF(COUNTIFS(Data_Long!$A$6:$A$243,H$5,Data_Long!$B$6:$B$243,$A86)=0,"not published",IF(COUNTIFS(Data_Long!$A$6:$A$243,H$5,Data_Long!$B$6:$B$243,$A86,Data_Long!$F$6:$F$243,"DERIVED")>0,"DERIVED","FACT")) -> FACT | I86: =IF(COUNTIFS(Data_Long!$A$6:$A$243,I$5,Data_Long!$B$6:$B$243,$A86)=0,"not published",IF(COUNTIFS(Data_Long!$A$6:$A$243,I$5,Data_Long!$B$6:$B$243,$A86,Data_Long!$F$6:$F$243,"DERIVED")>0,"DERIVED","FACT")) -> not published | J86: =IF(COUNTIFS(Data_Long!$A$6:$A$243,J$5,Data_Long!$B$6:$B$243,$A86)=0,"not published",IF(COUNTIFS(Data_Long!$A$6:$A$243,J$5,Data_Long!$B$6:$B$243,$A86,Data_Long!$F$6:$F$243,"DERIVED")>0,"DERIVED","FACT")) -> FACT

Sheet Data_Long
A1: Data_Long - controlled import of core.fact_financial (analysis window)
A2: Source: PostgreSQL porsche_lens, core.fact_financial filtered on dim_period.in_analysis_window (2023-H1..2026-H1). Blue = imported value (do not edit). K = rows with the same period_code + var_id (must be 1); L = value read back from Data_Panel; M = |L - D| (must be 0).
A3: Rows imported: 238 | Export query: see 03_SQL/12_export_mart.sql conventions; re-import by replacing rows 6-243.
A5: period_code | B5: var_id | C5: var_name | D5: value | E5: unit_std | F5: value_label | G5: origin | H5: source_id | I5: source_ref | J5: rounding | K5: dup_count | L5: panel_readback | M5: readback_diff
A6: 2023-H1 | B6: A01 | C6: Automotive sales revenue | D6: 18892 | E6: EUR m | F6: FACT | G6: MANUAL | H6: S002 | I6: 9 (Automotive EBITDA margin table) | J6: EUR 1m | K6: =COUNTIFS($A$6:$A$243,A6,$B$6:$B$243,B6) -> 1 | L6: =IF(COUNTIF(Data_Panel!$A$6:$A$44,B6)=0,"not in panel",IF(A6=Data_Panel!$D$5,SUMIFS(Data_Panel!$D$6:$D$44,Data_Panel!$A$6:$A$44,B6),IF(A6=Data_Panel!$E$5,SUMIFS(Data_Panel!$E$6:$E$44,Data_Panel!$A$6:$A$44,B6),IF(A6=Data_Panel!$F$5,SUMIFS(Data_Panel!$F$6:$F$44,Data_Panel!$A$6:$A$44,B6),IF(A6=Data_Panel!$G$5,SUMIFS(Data_Panel!$G$6:$G$44,Data_Panel!$A$6:$A$44,B6),IF(A6=Data_Panel!$H$5,SUMIFS(Data_Panel!$H$6:$H$44,Data_Panel!$A$6:$A$44,B6),IF(A6=Data_Panel!$I$5,SUMIFS(Data_Panel!$I$6:$I$44,Data_Panel!$A$6:$A$44,B6),IF(A6=Data_Panel!$J$5,SUMIFS(Data_Panel!$J$6:$J$44,Data_Panel!$A$6:$A$44,B6),"period not in panel")))))))) -> 18892 | M6: =IF(L6="not in panel",0,ABS(N(L6)-D6)) -> 0
A7: 2023-H1 | B7: A02 | C7: Automotive operating profit | D7: 3653 | E7: EUR m | F7: FACT | G7: MANUAL | H7: S002 | I7: 9 (Automotive EBITDA margin table) | J7: EUR 1m | K7: =COUNTIFS($A$6:$A$243,A7,$B$6:$B$243,B7) -> 1 | L7: =IF(COUNTIF(Data_Panel!$A$6:$A$44,B7)=0,"not in panel",IF(A7=Data_Panel!$D$5,SUMIFS(Data_Panel!$D$6:$D$44,Data_Panel!$A$6:$A$44,B7),IF(A7=Data_Panel!$E$5,SUMIFS(Data_Panel!$E$6:$E$44,Data_Panel!$A$6:$A$44,B7),IF(A7=Data_Panel!$F$5,SUMIFS(Data_Panel!$F$6:$F$44,Data_Panel!$A$6:$A$44,B7),IF(A7=Data_Panel!$G$5,SUMIFS(Data_Panel!$G$6:$G$44,Data_Panel!$A$6:$A$44,B7),IF(A7=Data_Panel!$H$5,SUMIFS(Data_Panel!$H$6:$H$44,Data_Panel!$A$6:$A$44,B7),IF(A7=Data_Panel!$I$5,SUMIFS(Data_Panel!$I$6:$I$44,Data_Panel!$A$6:$A$44,B7),IF(A7=Data_Panel!$J$5,SUMIFS(Data_Panel!$J$6:$J$44,Data_Panel!$A$6:$A$44,B7),"period not in panel")))))))) -> 3653 | M7: =IF(L7="not in panel",0,ABS(N(L7)-D7)) -> 0
A8: 2023-H1 | B8: A03 | C8: Automotive EBITDA | D8: 4829 | E8: EUR m | F8: FACT | G8: MANUAL | H8: S002 | I8: 9 (Automotive EBITDA margin table) | J8: EUR 1m | K8: =COUNTIFS($A$6:$A$243,A8,$B$6:$B$243,B8) -> 1 | L8: =IF(COUNTIF(Data_Panel!$A$6:$A$44,B8)=0,"not in panel",IF(A8=Data_Panel!$D$5,SUMIFS(Data_Panel!$D$6:$D$44,Data_Panel!$A$6:$A$44,B8),IF(A8=Data_Panel!$E$5,SUMIFS(Data_Panel!$E$6:$E$44,Data_Panel!$A$6:$A$44,B8),IF(A8=Data_Panel!$F$5,SUMIFS(Data_Panel!$F$6:$F$44,Data_Panel!$A$6:$A$44,B8),IF(A8=Data_Panel!$G$5,SUMIFS(Data_Panel!$G$6:$G$44,Data_Panel!$A$6:$A$44,B8),IF(A8=Data_Panel!$H$5,SUMIFS(Data_Panel!$H$6:$H$44,Data_Panel!$A$6:$A$44,B8),IF(A8=Data_Panel!$I$5,SUMIFS(Data_Panel!$I$6:$I$44,Data_Panel!$A$6:$A$44,B8),IF(A8=Data_Panel!$J$5,SUMIFS(Data_Panel!$J$6:$J$44,Data_Panel!$A$6:$A$44,B8),"period not in panel")))))))) -> 4829 | M8: =IF(L8="not in panel",0,ABS(N(L8)-D8)) -> 0
A9: 2023-H1 | B9: A04 | C9: Automotive EBITDA margin | D9: 25.6 | E9: % | F9: FACT | G9: MANUAL | H9: S002 | I9: 9 (Automotive EBITDA margin table) | J9: 0.1pp | K9: =COUNTIFS($A$6:$A$243,A9,$B$6:$B$243,B9) -> 1 | L9: =IF(COUNTIF(Data_Panel!$A$6:$A$44,B9)=0,"not in panel",IF(A9=Data_Panel!$D$5,SUMIFS(Data_Panel!$D$6:$D$44,Data_Panel!$A$6:$A$44,B9),IF(A9=Data_Panel!$E$5,SUMIFS(Data_Panel!$E$6:$E$44,Data_Panel!$A$6:$A$44,B9),IF(A9=Data_Panel!$F$5,SUMIFS(Data_Panel!$F$6:$F$44,Data_Panel!$A$6:$A$44,B9),IF(A9=Data_Panel!$G$5,SUMIFS(Data_Panel!$G$6:$G$44,Data_Panel!$A$6:$A$44,B9),IF(A9=Data_Panel!$H$5,SUMIFS(Data_Panel!$H$6:$H$44,Data_Panel!$A$6:$A$44,B9),IF(A9=Data_Panel!$I$5,SUMIFS(Data_Panel!$I$6:$I$44,Data_Panel!$A$6:$A$44,B9),IF(A9=Data_Panel!$J$5,SUMIFS(Data_Panel!$J$6:$J$44,Data_Panel!$A$6:$A$44,B9),"period not in panel")))))))) -> 25.6 | M9: =IF(L9="not in panel",0,ABS(N(L9)-D9)) -> 0
A10: 2023-H1 | B10: A05 | C10: Automotive R&D costs (total) | D10: 1545 | E10: EUR m | F10: FACT | G10: MANUAL | H10: S002 | I10: 29 (Note 3) | J10: EUR 1m | K10: =COUNTIFS($A$6:$A$243,A10,$B$6:$B$243,B10) -> 1 | L10: =IF(COUNTIF(Data_Panel!$A$6:$A$44,B10)=0,"not in panel",IF(A10=Data_Panel!$D$5,SUMIFS(Data_Panel!$D$6:$D$44,Data_Panel!$A$6:$A$44,B10),IF(A10=Data_Panel!$E$5,SUMIFS(Data_Panel!$E$6:$E$44,Data_Panel!$A$6:$A$44,B10),IF(A10=Data_Panel!$F$5,SUMIFS(Data_Panel!$F$6:$F$44,Data_Panel!$A$6:$A$44,B10),IF(A10=Data_Panel!$G$5,SUMIFS(Data_Panel!$G$6:$G$44,Data_Panel!$A$6:$A$44,B10),IF(A10=Data_Panel!$H$5,SUMIFS(Data_Panel!$H$6:$H$44,Data_Panel!$A$6:$A$44,B10),IF(A10=Data_Panel!$I$5,SUMIFS(Data_Panel!$I$6:$I$44,Data_Panel!$A$6:$A$44,B10),IF(A10=Data_Panel!$J$5,SUMIFS(Data_Panel!$J$6:$J$44,Data_Panel!$A$6:$A$44,B10),"period not in panel")))))))) -> 1545 | M10: =IF(L10="not in panel",0,ABS(N(L10)-D10)) -> 0
A11: 2023-H1 | B11: A06 | C11: Automotive capitalised development costs | D11: 1201 | E11: EUR m | F11: FACT | G11: MANUAL | H11: S002 | I11: 29 (Note 3) | J11: EUR 1m | K11: =COUNTIFS($A$6:$A$243,A11,$B$6:$B$243,B11) -> 1 | L11: =IF(COUNTIF(Data_Panel!$A$6:$A$44,B11)=0,"not in panel",IF(A11=Data_Panel!$D$5,SUMIFS(Data_Panel!$D$6:$D$44,Data_Panel!$A$6:$A$44,B11),IF(A11=Data_Panel!$E$5,SUMIFS(Data_Panel!$E$6:$E$44,Data_Panel!$A$6:$A$44,B11),IF(A11=Data_Panel!$F$5,SUMIFS(Data_Panel!$F$6:$F$44,Data_Panel!$A$6:$A$44,B11),IF(A11=Data_Panel!$G$5,SUMIFS(Data_Panel!$G$6:$G$44,Data_Panel!$A$6:$A$44,B11),IF(A11=Data_Panel!$H$5,SUMIFS(Data_Panel!$H$6:$H$44,Data_Panel!$A$6:$A$44,B11),IF(A11=Data_Panel!$I$5,SUMIFS(Data_Panel!$I$6:$I$44,Data_Panel!$A$6:$A$44,B11),IF(A11=Data_Panel!$J$5,SUMIFS(Data_Panel!$J$6:$J$44,Data_Panel!$A$6:$A$44,B11),"period not in panel")))))))) -> 1201 | M11: =IF(L11="not in panel",0,ABS(N(L11)-D11)) -> 0
A12: 2023-H1 | B12: A07 | C12: Capitalisation rate | D12: 77.7 | E12: % | F12: FACT | G12: MANUAL | H12: S002 | I12: 29 (Note 3) | J12: 0.1pp | K12: =COUNTIFS($A$6:$A$243,A12,$B$6:$B$243,B12) -> 1 | L12: =IF(COUNTIF(Data_Panel!$A$6:$A$44,B12)=0,"not in panel",IF(A12=Data_Panel!$D$5,SUMIFS(Data_Panel!$D$6:$D$44,Data_Panel!$A$6:$A$44,B12),IF(A12=Data_Panel!$E$5,SUMIFS(Data_Panel!$E$6:$E$44,Data_Panel!$A$6:$A$44,B12),IF(A12=Data_Panel!$F$5,SUMIFS(Data_Panel!$F$6:$F$44,Data_Panel!$A$6:$A$44,B12),IF(A12=Data_Panel!$G$5,SUMIFS(Data_Panel!$G$6:$G$44,Data_Panel!$A$6:$A$44,B12),IF(A12=Data_Panel!$H$5,SUMIFS(Data_Panel!$H$6:$H$44,Data_Panel!$A$6:$A$44,B12),IF(A12=Data_Panel!$I$5,SUMIFS(Data_Panel!$I$6:$I$44,Data_Panel!$A$6:$A$44,B12),IF(A12=Data_Panel!$J$5,SUMIFS(Data_Panel!$J$6:$J$44,Data_Panel!$A$6:$A$44,B12),"period not in panel")))))))) -> 77.7 | M12: =IF(L12="not in panel",0,ABS(N(L12)-D12)) -> 0
A13: 2023-H1 | B13: A08 | C13: Expensed automotive R&D | D13: 343 | E13: EUR m | F13: FACT | G13: MANUAL | H13: S005 | I13: 28 (prior-year column) | J13: EUR 1m | K13: =COUNTIFS($A$6:$A$243,A13,$B$6:$B$243,B13) -> 1 | L13: =IF(COUNTIF(Data_Panel!$A$6:$A$44,B13)=0,"not in panel",IF(A13=Data_Panel!$D$5,SUMIFS(Data_Panel!$D$6:$D$44,Data_Panel!$A$6:$A$44,B13),IF(A13=Data_Panel!$E$5,SUMIFS(Data_Panel!$E$6:$E$44,Data_Panel!$A$6:$A$44,B13),IF(A13=Data_Panel!$F$5,SUMIFS(Data_Panel!$F$6:$F$44,Data_Panel!$A$6:$A$44,B13),IF(A13=Data_Panel!$G$5,SUMIFS(Data_Panel!$G$6:$G$44,Data_Panel!$A$6:$A$44,B13),IF(A13=Data_Panel!$H$5,SUMIFS(Data_Panel!$H$6:$H$44,Data_Panel!$A$6:$A$44,B13),IF(A13=Data_Panel!$I$5,SUMIFS(Data_Panel!$I$6:$I$44,Data_Panel!$A$6:$A$44,B13),IF(A13=Data_Panel!$J$5,SUMIFS(Data_Panel!$J$6:$J$44,Data_Panel!$A$6:$A$44,B13),"period not in panel")))))))) -> 343 | M13: =IF(L13="not in panel",0,ABS(N(L13)-D13)) -> 0
A14: 2023-H1 | B14: A09 | C14: Amortisation of capitalised R&D | D14: 427 | E14: EUR m | F14: FACT | G14: MANUAL | H14: S002 | I14: 29 (Note 3) | J14: EUR 1m | K14: =COUNTIFS($A$6:$A$243,A14,$B$6:$B$243,B14) -> 1 | L14: =IF(COUNTIF(Data_Panel!$A$6:$A$44,B14)=0,"not in panel",IF(A14=Data_Panel!$D$5,SUMIFS(Data_Panel!$D$6:$D$44,Data_Panel!$A$6:$A$44,B14),IF(A14=Data_Panel!$E$5,SUMIFS(Data_Panel!$E$6:$E$44,Data_Panel!$A$6:$A$44,B14),IF(A14=Data_Panel!$F$5,SUMIFS(Data_Panel!$F$6:$F$44,Data_Panel!$A$6:$A$44,B14),IF(A14=Data_Panel!$G$5,SUMIFS(Data_Panel!$G$6:$G$44,Data_Panel!$A$6:$A$44,B14),IF(A14=Data_Panel!$H$5,SUMIFS(Data_Panel!$H$6:$H$44,Data_Panel!$A$6:$A$44,B14),IF(A14=Data_Panel!$I$5,SUMIFS(Data_Panel!$I$6:$I$44,Data_Panel!$A$6:$A$44,B14),IF(A14=Data_Panel!$J$5,SUMIFS(Data_Panel!$J$6:$J$44,Data_Panel!$A$6:$A$44,B14),"period not in panel")))))))) -> 427 | M14: =IF(L14="not in panel",0,ABS(N(L14)-D14)) -> 0
A15: 2023-H1 | B15: A10 | C15: Automotive capex | D15: 866 | E15: EUR m | F15: FACT | G15: MANUAL | H15: S002 | I15: 3 (key figures) | J15: EUR 1m | K15: =COUNTIFS($A$6:$A$243,A15,$B$6:$B$243,B15) -> 1 | L15: =IF(COUNTIF(Data_Panel!$A$6:$A$44,B15)=0,"not in panel",IF(A15=Data_Panel!$D$5,SUMIFS(Data_Panel!$D$6:$D$44,Data_Panel!$A$6:$A$44,B15),IF(A15=Data_Panel!$E$5,SUMIFS(Data_Panel!$E$6:$E$44,Data_Panel!$A$6:$A$44,B15),IF(A15=Data_Panel!$F$5,SUMIFS(Data_Panel!$F$6:$F$44,Data_Panel!$A$6:$A$44,B15),IF(A15=Data_Panel!$G$5,SUMIFS(Data_Panel!$G$6:$G$44,Data_Panel!$A$6:$A$44,B15),IF(A15=Data_Panel!$H$5,SUMIFS(Data_Panel!$H$6:$H$44,Data_Panel!$A$6:$A$44,B15),IF(A15=Data_Panel!$I$5,SUMIFS(Data_Panel!$I$6:$I$44,Data_Panel!$A$6:$A$44,B15),IF(A15=Data_Panel!$J$5,SUMIFS(Data_Panel!$J$6:$J$44,Data_Panel!$A$6:$A$44,B15),"period not in panel")))))))) -> 866 | M15: =IF(L15="not in panel",0,ABS(N(L15)-D15)) -> 0
A16: 2023-H1 | B16: A11 | C16: Automotive depreciation on capex | D16: 749 | E16: EUR m | F16: DERIVED | G16: SQL_DERIVED | I16: A12 - A09: S002 9 (Automotive EBITDA margin table) minus S002 29 (Note 3) | J16: derived from EUR 1m inputs | K16: =COUNTIFS($A$6:$A$243,A16,$B$6:$B$243,B16) -> 1 | L16: =IF(COUNTIF(Data_Panel!$A$6:$A$44,B16)=0,"not in panel",IF(A16=Data_Panel!$D$5,SUMIFS(Data_Panel!$D$6:$D$44,Data_Panel!$A$6:$A$44,B16),IF(A16=Data_Panel!$E$5,SUMIFS(Data_Panel!$E$6:$E$44,Data_Panel!$A$6:$A$44,B16),IF(A16=Data_Panel!$F$5,SUMIFS(Data_Panel!$F$6:$F$44,Data_Panel!$A$6:$A$44,B16),IF(A16=Data_Panel!$G$5,SUMIFS(Data_Panel!$G$6:$G$44,Data_Panel!$A$6:$A$44,B16),IF(A16=Data_Panel!$H$5,SUMIFS(Data_Panel!$H$6:$H$44,Data_Panel!$A$6:$A$44,B16),IF(A16=Data_Panel!$I$5,SUMIFS(Data_Panel!$I$6:$I$44,Data_Panel!$A$6:$A$44,B16),IF(A16=Data_Panel!$J$5,SUMIFS(Data_Panel!$J$6:$J$44,Data_Panel!$A$6:$A$44,B16),"period not in panel")))))))) -> 749 | M16: =IF(L16="not in panel",0,ABS(N(L16)-D16)) -> 0
A17: 2023-H1 | B17: A12 | C17: Automotive total D&A | D17: 1176 | E17: EUR m | F17: FACT | G17: MANUAL | H17: S002 | I17: 9 (Automotive EBITDA margin table) | J17: EUR 1m | K17: =COUNTIFS($A$6:$A$243,A17,$B$6:$B$243,B17) -> 1 | L17: =IF(COUNTIF(Data_Panel!$A$6:$A$44,B17)=0,"not in panel",IF(A17=Data_Panel!$D$5,SUMIFS(Data_Panel!$D$6:$D$44,Data_Panel!$A$6:$A$44,B17),IF(A17=Data_Panel!$E$5,SUMIFS(Data_Panel!$E$6:$E$44,Data_Panel!$A$6:$A$44,B17),IF(A17=Data_Panel!$F$5,SUMIFS(Data_Panel!$F$6:$F$44,Data_Panel!$A$6:$A$44,B17),IF(A17=Data_Panel!$G$5,SUMIFS(Data_Panel!$G$6:$G$44,Data_Panel!$A$6:$A$44,B17),IF(A17=Data_Panel!$H$5,SUMIFS(Data_Panel!$H$6:$H$44,Data_Panel!$A$6:$A$44,B17),IF(A17=Data_Panel!$I$5,SUMIFS(Data_Panel!$I$6:$I$44,Data_Panel!$A$6:$A$44,B17),IF(A17=Data_Panel!$J$5,SUMIFS(Data_Panel!$J$6:$J$44,Data_Panel!$A$6:$A$44,B17),"period not in panel")))))))) -> 1176 | M17: =IF(L17="not in panel",0,ABS(N(L17)-D17)) -> 0
A18: 2023-H1 | B18: A13 | C18: Automotive net cash flow | D18: 2216.9809 | E18: EUR m | F18: FACT | G18: FACTSHEET | H18: S025 | I18: 02 - Automotive CF AA24 | J18: exact (EUR, converted to EUR m) | K18: =COUNTIFS($A$6:$A$243,A18,$B$6:$B$243,B18) -> 1 | L18: =IF(COUNTIF(Data_Panel!$A$6:$A$44,B18)=0,"not in panel",IF(A18=Data_Panel!$D$5,SUMIFS(Data_Panel!$D$6:$D$44,Data_Panel!$A$6:$A$44,B18),IF(A18=Data_Panel!$E$5,SUMIFS(Data_Panel!$E$6:$E$44,Data_Panel!$A$6:$A$44,B18),IF(A18=Data_Panel!$F$5,SUMIFS(Data_Panel!$F$6:$F$44,Data_Panel!$A$6:$A$44,B18),IF(A18=Data_Panel!$G$5,SUMIFS(Data_Panel!$G$6:$G$44,Data_Panel!$A$6:$A$44,B18),IF(A18=Data_Panel!$H$5,SUMIFS(Data_Panel!$H$6:$H$44,Data_Panel!$A$6:$A$44,B18),IF(A18=Data_Panel!$I$5,SUMIFS(Data_Panel!$I$6:$I$44,Data_Panel!$A$6:$A$44,B18),IF(A18=Data_Panel!$J$5,SUMIFS(Data_Panel!$J$6:$J$44,Data_Panel!$A$6:$A$44,B18),"period not in panel")))))))) -> 2216.9809 | M18: =IF(L18="not in panel",0,ABS(N(L18)-D18)) -> 0
A19: 2023-H1 | B19: A13a | C19: Automotive cash flows from operating activities | D19: 4391.6849 | E19: EUR m | F19: FACT | G19: FACTSHEET | H19: S025 | I19: 02 - Automotive CF AA22 | J19: exact (EUR, converted to EUR m) | K19: =COUNTIFS($A$6:$A$243,A19,$B$6:$B$243,B19) -> 1 | L19: =IF(COUNTIF(Data_Panel!$A$6:$A$44,B19)=0,"not in panel",IF(A19=Data_Panel!$D$5,SUMIFS(Data_Panel!$D$6:$D$44,Data_Panel!$A$6:$A$44,B19),IF(A19=Data_Panel!$E$5,SUMIFS(Data_Panel!$E$6:$E$44,Data_Panel!$A$6:$A$44,B19),IF(A19=Data_Panel!$F$5,SUMIFS(Data_Panel!$F$6:$F$44,Data_Panel!$A$6:$A$44,B19),IF(A19=Data_Panel!$G$5,SUMIFS(Data_Panel!$G$6:$G$44,Data_Panel!$A$6:$A$44,B19),IF(A19=Data_Panel!$H$5,SUMIFS(Data_Panel!$H$6:$H$44,Data_Panel!$A$6:$A$44,B19),IF(A19=Data_Panel!$I$5,SUMIFS(Data_Panel!$I$6:$I$44,Data_Panel!$A$6:$A$44,B19),IF(A19=Data_Panel!$J$5,SUMIFS(Data_Panel!$J$6:$J$44,Data_Panel!$A$6:$A$44,B19),"period not in panel")))))))) -> 4391.6849 | M19: =IF(L19="not in panel",0,ABS(N(L19)-D19)) -> 0
A20: 2023-H1 | B20: A13b | C20: Automotive investing activities of current operations | D20: -2174.704 | E20: EUR m | F20: FACT | G20: FACTSHEET | H20: S025 | I20: 02 - Automotive CF AA23 | J20: exact (EUR, converted to EUR m) | K20: =COUNTIFS($A$6:$A$243,A20,$B$6:$B$243,B20) -> 1 | L20: =IF(COUNTIF(Data_Panel!$A$6:$A$44,B20)=0,"not in panel",IF(A20=Data_Panel!$D$5,SUMIFS(Data_Panel!$D$6:$D$44,Data_Panel!$A$6:$A$44,B20),IF(A20=Data_Panel!$E$5,SUMIFS(Data_Panel!$E$6:$E$44,Data_Panel!$A$6:$A$44,B20),IF(A20=Data_Panel!$F$5,SUMIFS(Data_Panel!$F$6:$F$44,Data_Panel!$A$6:$A$44,B20),IF(A20=Data_Panel!$G$5,SUMIFS(Data_Panel!$G$6:$G$44,Data_Panel!$A$6:$A$44,B20),IF(A20=Data_Panel!$H$5,SUMIFS(Data_Panel!$H$6:$H$44,Data_Panel!$A$6:$A$44,B20),IF(A20=Data_Panel!$I$5,SUMIFS(Data_Panel!$I$6:$I$44,Data_Panel!$A$6:$A$44,B20),IF(A20=Data_Panel!$J$5,SUMIFS(Data_Panel!$J$6:$J$44,Data_Panel!$A$6:$A$44,B20),"period not in panel")))))))) -> -2174.704 | M20: =IF(L20="not in panel",0,ABS(N(L20)-D20)) -> 0
A21: 2023-H1 | B21: A14 | C21: Automotive net liquidity | D21: 6432.0234 | E21: EUR m | F21: FACT | G21: FACTSHEET | H21: S025 | I21: 02 - Automotive CF AA25 | J21: exact (EUR, converted to EUR m) | K21: =COUNTIFS($A$6:$A$243,A21,$B$6:$B$243,B21) -> 1 | L21: =IF(COUNTIF(Data_Panel!$A$6:$A$44,B21)=0,"not in panel",IF(A21=Data_Panel!$D$5,SUMIFS(Data_Panel!$D$6:$D$44,Data_Panel!$A$6:$A$44,B21),IF(A21=Data_Panel!$E$5,SUMIFS(Data_Panel!$E$6:$E$44,Data_Panel!$A$6:$A$44,B21),IF(A21=Data_Panel!$F$5,SUMIFS(Data_Panel!$F$6:$F$44,Data_Panel!$A$6:$A$44,B21),IF(A21=Data_Panel!$G$5,SUMIFS(Data_Panel!$G$6:$G$44,Data_Panel!$A$6:$A$44,B21),IF(A21=Data_Panel!$H$5,SUMIFS(Data_Panel!$H$6:$H$44,Data_Panel!$A$6:$A$44,B21),IF(A21=Data_Panel!$I$5,SUMIFS(Data_Panel!$I$6:$I$44,Data_Panel!$A$6:$A$44,B21),IF(A21=Data_Panel!$J$5,SUMIFS(Data_Panel!$J$6:$J$44,Data_Panel!$A$6:$A$44,B21),"period not in panel")))))))) -> 6432.0234 | M21: =IF(L21="not in panel",0,ABS(N(L21)-D21)) -> 0
