Workbook

Sheet README
A1: File | B1: PCL_02_Manual_Inputs.xlsx - Phase 2: hand-entry of the variables that exist only in Porsche PDFs.
A2: Why this file | B2: The Porsche fact sheets (S024/S025) are extracted by script. They do not contain segment, EBITDA, R&D, D&A, one-off, ASP or BEV data. Those ~150 values are entered here, each tied to a source and page.
A3: What you edit | B3: Nothing, unless a source value is corrected. The workbook was populated by the lead analyst (Phase 2) and is the controlled input record for the SQL database (export_to_csv.py).
A4: How to enter | B4: If a value must be corrected: type it exactly as printed, in the unit shown in column H (Unit_as_shown). Do not convert. EUR bn -> 0.7 ; EUR m -> 1116 ; % -> 18.3 ; EUR k -> 126. Negative amounts keep their sign as printed.
A5: Rounding | B5: Column M (Rounding_as_shown) states the precision of the source. Never add digits the source does not show.
A6: Blue / black | B6: Blue = your hard-coded input. Black = formula. Green = value pulled from another sheet.
A7: Example row | B7: Row 36 (A05, H1_2026 = 1116, S016 slide 25) was the template's example row; it is now an ordinary verified input (V1).
A8: Checks | B8: Sheet 'Checks' turns OK / CHECK / PENDING as you type. Every CHECK must be resolved or explained in Note before Phase 3.
A9: FS_Reference | B9: Group revenue, EBIT, vehicle sales and deliveries by half-year from the fact sheet S025 (FACT). Used only by the checks.
A10: Independent re-check | B10: Double_checked (column O) follows ONE rule, applied to every row; column S (Verification_basis) states the basis per row: Y = V1 verbatim quote from the document text, or V2 value confirmed by reconciliation to the independent fact sheet S025 (or DERIVED from V1 components). N = V3 automated extraction without independent confirmation, or V4 DERIVED with an unconfirmed premise. N/A = blank row (data gap). Live counts: sheet 'Checks', rows 13-16.
A11: Status | B11: Populated by the lead analyst on 2026-09-28 from Porsche primary documents. Blue = value as printed. Grey = deliberately blank (reason in Note). Label column distinguishes FACT and DERIVED. Source re-check (Oct 2026): rows M095 (X05 FY2023 = 2), M097 (X05 FY2024 = 3) and M143 (O06 FY2023 = 112) filled from the official reports; M099 (X05 FY2025) refined from 1,200 to the exact 1,195. One gap remains (M093, X04 FY2025: not disclosed).

Sheet Inputs
A1: Rec_ID | B1: Var_ID | C1: Variable | D1: Period | E1: Source_ID | F1: Page | G1: Fallback_source | H1: Unit_as_shown | I1: Value_as_shown | J1: Value_std | K1: Std_unit | L1: Label | M1: Rounding_as_shown | N1: Entered_By | O1: Double_checked (Y/N) | P1: Note | Q1: Key | R1: Instruction | S1: Verification_basis
A2: M001 | B2: A01 | C2: Automotive sales revenue | D2: H1_2023 | E2: S002 | F2: 9 (Automotive EBITDA margin table) | G2: S001 p.7/9/11 (EUR bn) | H2: EUR m | I2: 18892 | J2: =IF(I2="","",IF(H2="EUR bn",I2*1000,I2)) -> 18892 | K2: =IF(H2="EUR bn","EUR m",H2) -> EUR m | L2: FACT | M2: EUR 1m | N2: Lead analyst (Claude) | O2: Y | P2: Verbatim from document text | Q2: =B2&"|"&D2 -> A01|H1_2023 | S2: V1: verbatim quote from the document text
A3: M002 | B3: A01 | C3: Automotive sales revenue | D3: FY_2023 | E3: S026 | F3: Automotive results of operations (2023 in brackets) | G3: S003 p.56/60 (EUR bn) | H3: EUR m | I3: 37349 | J3: =IF(I3="","",IF(H3="EUR bn",I3*1000,I3)) -> 37349 | K3: =IF(H3="EUR bn","EUR m",H3) -> EUR m | L3: FACT | M3: EUR 1m | N3: Lead analyst (Claude) | O3: Y | P3: Verbatim from document text | Q3: =B3&"|"&D3 -> A01|FY_2023 | S3: V1: verbatim quote from the document text
A4: M003 | B4: A01 | C4: Automotive sales revenue | D4: H1_2024 | E4: S006 | F4: 10 (Automotive EBITDA margin table) | G4: S005 p.14/17/21 (EUR bn) | H4: EUR m | I4: 17695 | J4: =IF(I4="","",IF(H4="EUR bn",I4*1000,I4)) -> 17695 | K4: =IF(H4="EUR bn","EUR m",H4) -> EUR m | L4: FACT | M4: EUR 1m | N4: Lead analyst (Claude) | O4: Y | P4: Verbatim from document text | Q4: =B4&"|"&D4 -> A01|H1_2024 | S4: V1: verbatim quote from the document text
A5: M004 | B5: A01 | C5: Automotive sales revenue | D5: FY_2024 | E5: S026 | F5: Automotive results of operations | G5: S007 p.66/70 (EUR bn) | H5: EUR m | I5: 36438 | J5: =IF(I5="","",IF(H5="EUR bn",I5*1000,I5)) -> 36438 | K5: =IF(H5="EUR bn","EUR m",H5) -> EUR m | L5: FACT | M5: EUR 1m | N5: Lead analyst (Claude) | O5: Y | P5: Verbatim from document text | Q5: =B5&"|"&D5 -> A01|FY_2024 | S5: V1: verbatim quote from the document text
A6: M005 | B6: A01 | C6: Automotive sales revenue | D6: H1_2025 | E6: S010 | F6: 11 (Automotive EBITDA margin table) | G6: S009 p.29/33 (EUR bn) | H6: EUR m | I6: 16138 | J6: =IF(I6="","",IF(H6="EUR bn",I6*1000,I6)) -> 16138 | K6: =IF(H6="EUR bn","EUR m",H6) -> EUR m | L6: FACT | M6: EUR 1m | N6: Lead analyst (Claude) | O6: Y | P6: Verbatim from document text | Q6: =B6&"|"&D6 -> A01|H1_2025 | S6: V1: verbatim quote from the document text
A7: M006 | B7: A01 | C7: Automotive sales revenue | D7: FY_2025 | E7: S013 | F7: Automotive results of operations | G7: S011 p.11 (EUR bn) | H7: EUR m | I7: 32185 | J7: =IF(I7="","",IF(H7="EUR bn",I7*1000,I7)) -> 32185 | K7: =IF(H7="EUR bn","EUR m",H7) -> EUR m | L7: FACT | M7: EUR 1m | N7: Lead analyst (Claude) | O7: Y | P7: Verbatim from document text | Q7: =B7&"|"&D7 -> A01|FY_2025 | S7: V1: verbatim quote from the document text
A8: M007 | B8: A01 | C8: Automotive sales revenue | D8: H1_2026 | E8: S017 | F8: 12 (Automotive EBITDA margin table) | G8: S016 p.7/11 (EUR bn) | H8: EUR m | I8: 15158 | J8: =IF(I8="","",IF(H8="EUR bn",I8*1000,I8)) -> 15158 | K8: =IF(H8="EUR bn","EUR m",H8) -> EUR m | L8: FACT | M8: EUR 1m | N8: Lead analyst (Claude) | O8: Y | P8: Verbatim from document text | Q8: =B8&"|"&D8 -> A01|H1_2026 | S8: V1: verbatim quote from the document text
A9: M008 | B9: A02 | C9: Automotive operating profit | D9: H1_2023 | E9: S002 | F9: 9 (Automotive EBITDA margin table) | G9: S001 p.7/9/11 (EUR bn) | H9: EUR m | I9: 3653 | J9: =IF(I9="","",IF(H9="EUR bn",I9*1000,I9)) -> 3653 | K9: =IF(H9="EUR bn","EUR m",H9) -> EUR m | L9: FACT | M9: EUR 1m | N9: Lead analyst (Claude) | O9: Y | P9: Verbatim from document text | Q9: =B9&"|"&D9 -> A02|H1_2023 | S9: V1: verbatim quote from the document text
A10: M009 | B10: A02 | C10: Automotive operating profit | D10: FY_2023 | E10: S026 | F10: Automotive results of operations (2023 in brackets) | G10: S003 p.56/60 (EUR bn) | H10: EUR m | I10: 6938 | J10: =IF(I10="","",IF(H10="EUR bn",I10*1000,I10)) -> 6938 | K10: =IF(H10="EUR bn","EUR m",H10) -> EUR m | L10: FACT | M10: EUR 1m | N10: Lead analyst (Claude) | O10: Y | P10: Verbatim from document text | Q10: =B10&"|"&D10 -> A02|FY_2023 | S10: V1: verbatim quote from the document text
A11: M010 | B11: A02 | C11: Automotive operating profit | D11: H1_2024 | E11: S006 | F11: 10 (Automotive EBITDA margin table) | G11: S005 p.14/17/21 (EUR bn) | H11: EUR m | I11: 2904 | J11: =IF(I11="","",IF(H11="EUR bn",I11*1000,I11)) -> 2904 | K11: =IF(H11="EUR bn","EUR m",H11) -> EUR m | L11: FACT | M11: EUR 1m | N11: Lead analyst (Claude) | O11: Y | P11: Verbatim from document text | Q11: =B11&"|"&D11 -> A02|H1_2024 | S11: V1: verbatim quote from the document text
A12: M011 | B12: A02 | C12: Automotive operating profit | D12: FY_2024 | E12: S013 | F12: Automotive results of operations (2024 in brackets) | G12: S007 p.66/70 (EUR bn) | H12: EUR m | I12: 5286 | J12: =IF(I12="","",IF(H12="EUR bn",I12*1000,I12)) -> 5286 | K12: =IF(H12="EUR bn","EUR m",H12) -> EUR m | L12: FACT | M12: EUR 1m | N12: Lead analyst (Claude) | O12: Y | P12: Verbatim from document text; also S026 | Q12: =B12&"|"&D12 -> A02|FY_2024 | S12: V1: verbatim quote from the document text
A13: M012 | B13: A02 | C13: Automotive operating profit | D13: H1_2025 | E13: S010 | F13: 11 (Automotive EBITDA margin table) | G13: S009 p.29/33 (EUR bn) | H13: EUR m | I13: 832 | J13: =IF(I13="","",IF(H13="EUR bn",I13*1000,I13)) -> 832 | K13: =IF(H13="EUR bn","EUR m",H13) -> EUR m | L13: FACT | M13: EUR 1m | N13: Lead analyst (Claude) | O13: Y | P13: Verbatim from document text | Q13: =B13&"|"&D13 -> A02|H1_2025 | S13: V1: verbatim quote from the document text
... A22: M021 | B22: A03 | C22: Automotive EBITDA | D22: H1_2026 | E22: S017 | F22: 12 (Automotive EBITDA margin table) | G22: S016 p.7/11 (EUR bn) | H22: EUR m | I22: 2767 | J22: =IF(I22="","",IF(H22="EUR bn",I22*1000,I22)) -> 2767 | K22: =IF(H22="EUR bn","EUR m",H22) -> EUR m | L22: FACT | M22: EUR 1m | N22: Lead analyst (Claude) | O22: Y | P22: Verbatim from document text | Q22: =B22&"|"&D22 -> A03|H1_2026 | S22: V1: verbatim quote from the document text
A23: M022 | B23: A04 | C23: Automotive EBITDA margin | D23: H1_2023 | E23: S002 | F23: 9 (Automotive EBITDA margin table) | G23: S001 p.7/9/11 (EUR bn) | H23: % | I23: 25.6 | J23: =IF(I23="","",IF(H23="EUR bn",I23*1000,I23)) -> 25.6 | K23: =IF(H23="EUR bn","EUR m",H23) -> % | L23: FACT | M23: 0.1pp | N23: Lead analyst (Claude) | O23: Y | P23: Verbatim from document text | Q23: =B23&"|"&D23 -> A04|H1_2023 | R23: Enter 18.3 for 18.3% | S23: V1: verbatim quote from the document text
A24: M023 | B24: A04 | C24: Automotive EBITDA margin | D24: FY_2023 | E24: S026 | F24: Automotive results of operations (2023 in brackets) | G24: S003 p.56/60 (EUR bn) | H24: % | I24: 25.7 | J24: =IF(I24="","",IF(H24="EUR bn",I24*1000,I24)) -> 25.7 | K24: =IF(H24="EUR bn","EUR m",H24) -> % | L24: FACT | M24: 0.1pp | N24: Lead analyst (Claude) | O24: Y | P24: Verbatim from document text | Q24: =B24&"|"&D24 -> A04|FY_2023 | R24: Enter 18.3 for 18.3% | S24: V1: verbatim quote from the document text
A25: M024 | B25: A04 | C25: Automotive EBITDA margin | D25: H1_2024 | E25: S006 | F25: 10 (Automotive EBITDA margin table) | G25: S005 p.14/17/21 (EUR bn) | H25: % | I25: 24.1 | J25: =IF(I25="","",IF(H25="EUR bn",I25*1000,I25)) -> 24.1 | K25: =IF(H25="EUR bn","EUR m",H25) -> % | L25: FACT | M25: 0.1pp | N25: Lead analyst (Claude) | O25: Y | P25: Verbatim from document text | Q25: =B25&"|"&D25 -> A04|H1_2024 | R25: Enter 18.3 for 18.3% | S25: V1: verbatim quote from the document text
A26: M025 | B26: A04 | C26: Automotive EBITDA margin | D26: FY_2024 | E26: S026 | F26: Automotive results of operations | G26: S007 p.66/70 (EUR bn) | H26: % | I26: 22.7 | J26: =IF(I26="","",IF(H26="EUR bn",I26*1000,I26)) -> 22.7 | K26: =IF(H26="EUR bn","EUR m",H26) -> % | L26: FACT | M26: 0.1pp | N26: Lead analyst (Claude) | O26: Y | P26: Verbatim from document text | Q26: =B26&"|"&D26 -> A04|FY_2024 | R26: Enter 18.3 for 18.3% | S26: V1: verbatim quote from the document text
A27: M026 | B27: A04 | C27: Automotive EBITDA margin | D27: H1_2025 | E27: S010 | F27: 11 (Automotive EBITDA margin table) | G27: S009 p.29/33 (EUR bn) | H27: % | I27: 16 | J27: =IF(I27="","",IF(H27="EUR bn",I27*1000,I27)) -> 16 | K27: =IF(H27="EUR bn","EUR m",H27) -> % | L27: FACT | M27: 0.1pp | N27: Lead analyst (Claude) | O27: Y | P27: Verbatim from document text | Q27: =B27&"|"&D27 -> A04|H1_2025 | R27: Enter 18.3 for 18.3% | S27: V1: verbatim quote from the document text
A28: M027 | B28: A04 | C28: Automotive EBITDA margin | D28: FY_2025 | E28: S013 | F28: Automotive results of operations | G28: S011 p.11 (EUR bn) | H28: % | I28: 13.3 | J28: =IF(I28="","",IF(H28="EUR bn",I28*1000,I28)) -> 13.3 | K28: =IF(H28="EUR bn","EUR m",H28) -> % | L28: FACT | M28: 0.1pp | N28: Lead analyst (Claude) | O28: Y | P28: Verbatim from document text | Q28: =B28&"|"&D28 -> A04|FY_2025 | R28: Enter 18.3 for 18.3% | S28: V1: verbatim quote from the document text
A29: M028 | B29: A04 | C29: Automotive EBITDA margin | D29: H1_2026 | E29: S017 | F29: 12 (Automotive EBITDA margin table) | G29: S016 p.7/11 (EUR bn) | H29: % | I29: 18.3 | J29: =IF(I29="","",IF(H29="EUR bn",I29*1000,I29)) -> 18.3 | K29: =IF(H29="EUR bn","EUR m",H29) -> % | L29: FACT | M29: 0.1pp | N29: Lead analyst (Claude) | O29: Y | P29: Verbatim from document text | Q29: =B29&"|"&D29 -> A04|H1_2026 | R29: Enter 18.3 for 18.3% | S29: V1: verbatim quote from the document text
A30: M029 | B30: A05 | C30: Automotive R&D costs (total) | D30: H1_2023 | E30: S002 | F30: 29 (Note 3) | G30: S002 p.6 | H30: EUR m | I30: 1545 | J30: =IF(I30="","",IF(H30="EUR bn",I30*1000,I30)) -> 1545 | K30: =IF(H30="EUR bn","EUR m",H30) -> EUR m | L30: FACT | M30: EUR 1m | N30: Lead analyst (Claude) | O30: Y | P30: Verbatim from document text; same figure as prior-year column in S006 p.8 | Q30: =B30&"|"&D30 -> A05|H1_2023 | S30: V1: verbatim quote from the document text
A31: M030 | B31: A05 | C31: Automotive R&D costs (total) | D31: FY_2023 | E31: S011 | F31: 34 | G31: S003 p.66 | H31: EUR m | I31: 2834 | J31: =IF(I31="","",IF(H31="EUR bn",I31*1000,I31)) -> 2834 | K31: =IF(H31="EUR bn","EUR m",H31) -> EUR m | L31: FACT | M31: EUR 1m | N31: Lead analyst (Claude) | O31: Y | P31: Verbatim from document text | Q31: =B31&"|"&D31 -> A05|FY_2023 | S31: V1: verbatim quote from the document text
A32: M031 | B32: A05 | C32: Automotive R&D costs (total) | D32: H1_2024 | E32: S016 | F32: 25 | G32: S005 p.28 | H32: EUR m | I32: 1665 | J32: =IF(I32="","",IF(H32="EUR bn",I32*1000,I32)) -> 1665 | K32: =IF(H32="EUR bn","EUR m",H32) -> EUR m | L32: FACT | M32: EUR 1m | N32: Lead analyst (Claude) | O32: Y | P32: Verbatim from document text | Q32: =B32&"|"&D32 -> A05|H1_2024 | S32: V1: verbatim quote from the document text
A33: M032 | B33: A05 | C33: Automotive R&D costs (total) | D33: FY_2024 | E33: S011 | F33: 34 | G33: S007 p.78 | H33: EUR m | I33: 2528 | J33: =IF(I33="","",IF(H33="EUR bn",I33*1000,I33)) -> 2528 | K33: =IF(H33="EUR bn","EUR m",H33) -> EUR m | L33: FACT | M33: EUR 1m | N33: Lead analyst (Claude) | O33: Y | P33: Verbatim from document text | Q33: =B33&"|"&D33 -> A05|FY_2024 | S33: V1: verbatim quote from the document text
A34: M033 | B34: A05 | C34: Automotive R&D costs (total) | D34: H1_2025 | E34: S016 | F34: 25 | G34: S009 p.43 | H34: EUR m | I34: 1264 | J34: =IF(I34="","",IF(H34="EUR bn",I34*1000,I34)) -> 1264 | K34: =IF(H34="EUR bn","EUR m",H34) -> EUR m | L34: FACT | M34: EUR 1m | N34: Lead analyst (Claude) | O34: Y | P34: Verbatim from document text. Restated: S010 p.9 (published July 2025) showed 1,258; S016 (latest) shows 1,264. Latest-document rule applied (AF-09). | Q34: =B34&"|"&D34 -> A05|H1_2025 | S34: V1: verbatim quote from the document text
A35: M034 | B35: A05 | C35: Automotive R&D costs (total) | D35: FY_2025 | E35: S011 | F35: 34 | H35: EUR m | I35: 2292 | J35: =IF(I35="","",IF(H35="EUR bn",I35*1000,I35)) -> 2292 | K35: =IF(H35="EUR bn","EUR m",H35) -> EUR m | L35: FACT | M35: EUR 1m | N35: Lead analyst (Claude) | O35: Y | P35: Verbatim from document text | Q35: =B35&"|"&D35 -> A05|FY_2025 | S35: V1: verbatim quote from the document text
A36: M035 | B36: A05 | C36: Automotive R&D costs (total) | D36: H1_2026 | E36: S016 | F36: 25 | H36: EUR m | I36: 1116 | J36: =IF(I36="","",IF(H36="EUR bn",I36*1000,I36)) -> 1116 | K36: =IF(H36="EUR bn","EUR m",H36) -> EUR m | L36: FACT | M36: EUR 1m | N36: Lead analyst (Claude) | O36: Y | P36: Verbatim from document text | Q36: =B36&"|"&D36 -> A05|H1_2026 | S36: V1: verbatim quote from the document text
A37: M036 | B37: A06 | C37: Automotive capitalised development costs | D37: H1_2023 | E37: S002 | F37: 29 (Note 3) | G37: S002 p.6 | H37: EUR m | I37: 1201 | J37: =IF(I37="","",IF(H37="EUR bn",I37*1000,I37)) -> 1201 | K37: =IF(H37="EUR bn","EUR m",H37) -> EUR m | L37: FACT | M37: EUR 1m | N37: Lead analyst (Claude) | O37: Y | P37: Verbatim from document text | Q37: =B37&"|"&D37 -> A06|H1_2023 | S37: V1: verbatim quote from the document text
A38: M037 | B38: A06 | C38: Automotive capitalised development costs | D38: FY_2023 | E38: S011 | F38: 34 | G38: S003 p.66 | H38: EUR m | I38: 2081 | J38: =IF(I38="","",IF(H38="EUR bn",I38*1000,I38)) -> 2081 | K38: =IF(H38="EUR bn","EUR m",H38) -> EUR m | L38: FACT | M38: EUR 1m | N38: Lead analyst (Claude) | O38: Y | P38: Verbatim from document text | Q38: =B38&"|"&D38 -> A06|FY_2023 | S38: V1: verbatim quote from the document text
A39: M038 | B39: A06 | C39: Automotive capitalised development costs | D39: H1_2024 | E39: S016 | F39: 25 | G39: S005 p.28 | H39: EUR m | I39: 1123 | J39: =IF(I39="","",IF(H39="EUR bn",I39*1000,I39)) -> 1123 | K39: =IF(H39="EUR bn","EUR m",H39) -> EUR m | L39: FACT | M39: EUR 1m | N39: Lead analyst (Claude) | O39: Y | P39: Verbatim from document text | Q39: =B39&"|"&D39 -> A06|H1_2024 | S39: V1: verbatim quote from the document text
A40: M039 | B40: A06 | C40: Automotive capitalised development costs | D40: FY_2024 | E40: S011 | F40: 34 | G40: S007 p.78 | H40: EUR m | I40: 1583 | J40: =IF(I40="","",IF(H40="EUR bn",I40*1000,I40)) -> 1583 | K40: =IF(H40="EUR bn","EUR m",H40) -> EUR m | L40: FACT | M40: EUR 1m | N40: Lead analyst (Claude) | O40: Y | P40: Verbatim from document text | Q40: =B40&"|"&D40 -> A06|FY_2024 | S40: V1: verbatim quote from the document text
A41: M040 | B41: A06 | C41: Automotive capitalised development costs | D41: H1_2025 | E41: S016 | F41: 25 | G41: S009 p.43 | H41: EUR m | I41: 575 | J41: =IF(I41="","",IF(H41="EUR bn",I41*1000,I41)) -> 575 | K41: =IF(H41="EUR bn","EUR m",H41) -> EUR m | L41: FACT | M41: EUR 1m | N41: Lead analyst (Claude) | O41: Y | P41: Verbatim from document text | Q41: =B41&"|"&D41 -> A06|H1_2025 | S41: V1: verbatim quote from the document text
A42: M041 | B42: A06 | C42: Automotive capitalised development costs | D42: FY_2025 | E42: S011 | F42: 34 | H42: EUR m | I42: 963 | J42: =IF(I42="","",IF(H42="EUR bn",I42*1000,I42)) -> 963 | K42: =IF(H42="EUR bn","EUR m",H42) -> EUR m | L42: FACT | M42: EUR 1m | N42: Lead analyst (Claude) | O42: Y | P42: Verbatim from document text | Q42: =B42&"|"&D42 -> A06|FY_2025 | S42: V1: verbatim quote from the document text
A43: M042 | B43: A06 | C43: Automotive capitalised development costs | D43: H1_2026 | E43: S016 | F43: 25 | H43: EUR m | I43: 487 | J43: =IF(I43="","",IF(H43="EUR bn",I43*1000,I43)) -> 487 | K43: =IF(H43="EUR bn","EUR m",H43) -> EUR m | L43: FACT | M43: EUR 1m | N43: Lead analyst (Claude) | O43: Y | P43: Verbatim from document text | Q43: =B43&"|"&D43 -> A06|H1_2026 | S43: V1: verbatim quote from the document text
A44: M043 | B44: A07 | C44: Capitalisation rate | D44: H1_2023 | E44: S002 | F44: 29 (Note 3) | G44: S002 p.6 | H44: % | I44: 77.7 | J44: =IF(I44="","",IF(H44="EUR bn",I44*1000,I44)) -> 77.7 | K44: =IF(H44="EUR bn","EUR m",H44) -> % | L44: FACT | M44: 0.1pp | N44: Lead analyst (Claude) | O44: Y | P44: Verbatim from document text | Q44: =B44&"|"&D44 -> A07|H1_2023 | R44: Enter 43.6 for 43.6% | S44: V1: verbatim quote from the document text
A45: M044 | B45: A07 | C45: Capitalisation rate | D45: FY_2023 | E45: S011 | F45: 34 | G45: S003 p.66 | H45: % | I45: 73.5 | J45: =IF(I45="","",IF(H45="EUR bn",I45*1000,I45)) -> 73.5 | K45: =IF(H45="EUR bn","EUR m",H45) -> % | L45: FACT | M45: 0.1pp | N45: Lead analyst (Claude) | O45: Y | P45: Verbatim from document text | Q45: =B45&"|"&D45 -> A07|FY_2023 | R45: Enter 43.6 for 43.6% | S45: V1: verbatim quote from the document text
A46: M045 | B46: A07 | C46: Capitalisation rate | D46: H1_2024 | E46: S016 | F46: 25 | G46: S005 p.28 | H46: % | I46: 67.5 | J46: =IF(I46="","",IF(H46="EUR bn",I46*1000,I46)) -> 67.5 | K46: =IF(H46="EUR bn","EUR m",H46) -> % | L46: FACT | M46: 0.1pp | N46: Lead analyst (Claude) | O46: Y | P46: Verbatim from document text | Q46: =B46&"|"&D46 -> A07|H1_2024 | R46: Enter 43.6 for 43.6% | S46: V1: verbatim quote from the document text
A47: M046 | B47: A07 | C47: Capitalisation rate | D47: FY_2024 | E47: S011 | F47: 34 | G47: S007 p.78 | H47: % | I47: 62.6 | J47: =IF(I47="","",IF(H47="EUR bn",I47*1000,I47)) -> 62.6 | K47: =IF(H47="EUR bn","EUR m",H47) -> % | L47: FACT | M47: 0.1pp | N47: Lead analyst (Claude) | O47: Y | P47: Verbatim from document text | Q47: =B47&"|"&D47 -> A07|FY_2024 | R47: Enter 43.6 for 43.6% | S47: V1: verbatim quote from the document text
A48: M047 | B48: A07 | C48: Capitalisation rate | D48: H1_2025 | E48: S016 | F48: 25 | G48: S009 p.43 | H48: % | I48: 45.5 | J48: =IF(I48="","",IF(H48="EUR bn",I48*1000,I48)) -> 45.5 | K48: =IF(H48="EUR bn","EUR m",H48) -> % | L48: FACT | M48: 0.1pp | N48: Lead analyst (Claude) | O48: Y | P48: Verbatim from document text | Q48: =B48&"|"&D48 -> A07|H1_2025 | R48: Enter 43.6 for 43.6% | S48: V1: verbatim quote from the document text
...

Sheet FS_Reference
A1: Period | B1: G01 Group revenue (EUR m) | C1: G07 Group EBIT (EUR m) | D1: O04 Vehicle sales (units) | E1: O01 Deliveries (units) | F1: Source | G1: G03 Gross profit (EUR m) | H1: G04+G05 SG&A (EUR m) | I1: G06 Net other operating result (EUR m)
A2: H1_2022 | B2: 17921.7 | C2: 3480.2 | D2: 148568 | E2: 145860 | F2: S025 fact sheet via pcl_extract_factsheets.py (FACT) - 2022 IFRS 17 restated | G2: 5053.6 | H2: -1722 | I2: 149
A3: FY_2022 | B3: 37637.4 | C3: 6772.4 | D3: 313721 | E3: 309884 | F3: S025 fact sheet via pcl_extract_factsheets.py (FACT) - 2022 IFRS 17 restated | G3: 10548.6 | H3: -4008.2 | I3: 231.9
A4: H1_2023 | B4: 20430.9 | C4: 3852.2 | D4: 170802 | E4: 167354 | F4: S025 fact sheet via pcl_extract_factsheets.py (FACT) | G4: 5909.4 | H4: -2168 | I4: 110.9
A5: FY_2023 | B5: 40529.6 | C5: 7284.3 | D5: 333605 | E5: 320221 | F5: S025 fact sheet via pcl_extract_factsheets.py (FACT) | G5: 11605.9 | H5: -4656.2 | I5: 334.6
A6: H1_2024 | B6: 19457 | C6: 3061.5 | D6: 151944 | E6: 155945 | F6: S025 fact sheet via pcl_extract_factsheets.py (FACT) | G6: 5206 | H6: -2331.1 | I6: 186.6
A7: FY_2024 | B7: 40083.3 | C7: 5636.9 | D7: 312620 | E7: 310718 | F7: S025 fact sheet via pcl_extract_factsheets.py (FACT) | G7: 10327.4 | H7: -4958.7 | I7: 268.1
A8: H1_2025 | B8: 18157.3 | C8: 1006.8 | D8: 135142 | E8: 146391 | F8: S025 fact sheet via pcl_extract_factsheets.py (FACT) | G8: 3363.9 | H8: -2288.2 | I8: -68.9
A9: FY_2025 | B9: 36271.6 | C9: 413.3 | D9: 265663 | E9: 279449 | F9: S025 fact sheet via pcl_extract_factsheets.py (FACT) | G9: 5050.9 | H9: -4694.2 | I9: 56.7
A10: H1_2026 | B10: 17229.5 | C10: 1348.2 | D10: 120508 | E10: 122306 | F10: S025 fact sheet via pcl_extract_factsheets.py (FACT) | G10: 3465.8 | H10: -2275.5 | I10: 157.9

Sheet Checks
A1: Period | B1: CHK1 R&D: A05 = A06 + A08 (+/-2) | C1: CHK2 Cap. rate: A06/A05 = A07 (+/-0.2pp) | D1: CHK3 D&A: A12 = A09 + A11 (+/-2) | E1: CHK4 EBITDA: A03 = A02 + A12 (+/-60) | F1: CHK5 Margin: A03/A01 = A04 (+/-0.15pp) | G1: CHK6 ASP: A01/vehicle sales = O06 (+/-1.5k) | H1: CHK7 Bridge: prior EBIT + B01..B04 = EBIT | I1: CHK8 Bridge SG&A: B03 = change in G04+G05 (fact sheet) | J1: CHK9 Bridge Other: B04 = change in G06 (fact sheet) | K1: CHK10 Bridge: B01 + B02 = change in gross profit G03 | L1: Bridge tolerance (EUR m) | M1: Entered rows | N1: Blank rows with explanation | O1: Rows expected
A2: H1_2023 | B2: =IF((COUNTIFS(Inputs!$Q$2:$Q$156,"A05|"&$A2,Inputs!$I$2:$I$156,"<>"))*(COUNTIFS(Inputs!$Q$2:$Q$156,"A06|"&$A2,Inputs!$I$2:$I$156,"<>"))*(COUNTIFS(Inputs!$Q$2:$Q$156,"A08|"&$A2,Inputs!$I$2:$I$156,"<>"))=0,"PENDING",IF(ABS(SUMIFS(Inputs!$J$2:$J$156,Inputs!$Q$2:$Q$156,"A05|"&$A2)-SUMIFS(Inputs!$J$2:$J$156,Inputs!$Q$2:$Q$156,"A06|"&$A2)-SUMIFS(Inputs!$J$2:$J$156,Inputs!$Q$2:$Q$156,"A08|"&$A2))<=2,"OK","CHECK")) -> OK | C2: =IF((COUNTIFS(Inputs!$Q$2:$Q$156,"A05|"&$A2,Inputs!$I$2:$I$156,"<>"))*(COUNTIFS(Inputs!$Q$2:$Q$156,"A06|"&$A2,Inputs!$I$2:$I$156,"<>"))*(COUNTIFS(Inputs!$Q$2:$Q$156,"A07|"&$A2,Inputs!$I$2:$I$156,"<>"))=0,"PENDING",IF(ABS(SUMIFS(Inputs!$J$2:$J$156,Inputs!$Q$2:$Q$156,"A06|"&$A2)/SUMIFS(Inputs!$J$2:$J$156,Inputs!$Q$2:$Q$156,"A05|"&$A2)*100-SUMIFS(Inputs!$J$2:$J$156,Inputs!$Q$2:$Q$156,"A07|"&$A2))<=0.2,"OK","CHECK")) -> OK | D2: ="N/A (A11 derived)" -> N/A (A11 derived) | E2: =IF((COUNTIFS(Inputs!$Q$2:$Q$156,"A03|"&$A2,Inputs!$I$2:$I$156,"<>"))*(COUNTIFS(Inputs!$Q$2:$Q$156,"A02|"&$A2,Inputs!$I$2:$I$156,"<>"))*(COUNTIFS(Inputs!$Q$2:$Q$156,"A12|"&$A2,Inputs!$I$2:$I$156,"<>"))=0,"PENDING",IF(ABS(SUMIFS(Inputs!$J$2:$J$156,Inputs!$Q$2:$Q$156,"A03|"&$A2)-SUMIFS(Inputs!$J$2:$J$156,Inputs!$Q$2:$Q$156,"A02|"&$A2)-SUMIFS(Inputs!$J$2:$J$156,Inputs!$Q$2:$Q$156,"A12|"&$A2))<=60,"OK","CHECK")) -> OK | F2: =IF((COUNTIFS(Inputs!$Q$2:$Q$156,"A03|"&$A2,Inputs!$I$2:$I$156,"<>"))*(COUNTIFS(Inputs!$Q$2:$Q$156,"A01|"&$A2,Inputs!$I$2:$I$156,"<>"))*(COUNTIFS(Inputs!$Q$2:$Q$156,"A04|"&$A2,Inputs!$I$2:$I$156,"<>"))=0,"PENDING",IF(ABS(SUMIFS(Inputs!$J$2:$J$156,Inputs!$Q$2:$Q$156,"A03|"&$A2)/SUMIFS(Inputs!$J$2:$J$156,Inputs!$Q$2:$Q$156,"A01|"&$A2)*100-SUMIFS(Inputs!$J$2:$J$156,Inputs!$Q$2:$Q$156,"A04|"&$A2))<=0.15,"OK","CHECK")) -> OK | G2: =IF((COUNTIFS(Inputs!$Q$2:$Q$156,"A01|"&$A2,Inputs!$I$2:$I$156,"<>"))*(COUNTIFS(Inputs!$Q$2:$Q$156,"O06|"&$A2,Inputs!$I$2:$I$156,"<>"))=0,IF(COUNTIFS(Inputs!$Q$2:$Q$156,"O06|"&$A2,Inputs!$I$2:$I$156,"",Inputs!$P$2:$P$156,"<>")>0,"N/A (blank - see Inputs note)","PENDING"),IF(ABS(SUMIFS(Inputs!$J$2:$J$156,Inputs!$Q$2:$Q$156,"A01|"&$A2)*1000/INDEX(FS_Reference!$D$2:$D$10,MATCH($A2,FS_Reference!$A$2:$A$10,0))-SUMIFS(Inputs!$J$2:$J$156,Inputs!$Q$2:$Q$156,"O06|"&$A2))<=1.5,"OK","CHECK")) -> OK | H2: ="N/A (bridge is qualitative)" -> N/A (bridge is qualitative) | I2: ="N/A (bridge is qualitative)" -> N/A (bridge is qualitative) | J2: ="N/A (bridge is qualitative)" -> N/A (bridge is qualitative) | K2: ="N/A (bridge is qualitative)" -> N/A (bridge is qualitative) | L2: 50 | M2: =COUNTIFS(Inputs!$D$2:$D$156,$A2,Inputs!$I$2:$I$156,"<>") -> 16 | N2: =COUNTIFS(Inputs!$D$2:$D$156,$A2,Inputs!$I$2:$I$156,"",Inputs!$P$2:$P$156,"<>") -> 0 | O2: =COUNTIFS(Inputs!$D$2:$D$156,$A2) -> 16
A3: FY_2023 | B3: =IF((COUNTIFS(Inputs!$Q$2:$Q$156,"A05|"&$A3,Inputs!$I$2:$I$156,"<>"))*(COUNTIFS(Inputs!$Q$2:$Q$156,"A06|"&$A3,Inputs!$I$2:$I$156,"<>"))*(COUNTIFS(Inputs!$Q$2:$Q$156,"A08|"&$A3,Inputs!$I$2:$I$156,"<>"))=0,"PENDING",IF(ABS(SUMIFS(Inputs!$J$2:$J$156,Inputs!$Q$2:$Q$156,"A05|"&$A3)-SUMIFS(Inputs!$J$2:$J$156,Inputs!$Q$2:$Q$156,"A06|"&$A3)-SUMIFS(Inputs!$J$2:$J$156,Inputs!$Q$2:$Q$156,"A08|"&$A3))<=2,"OK","CHECK")) -> OK | C3: =IF((COUNTIFS(Inputs!$Q$2:$Q$156,"A05|"&$A3,Inputs!$I$2:$I$156,"<>"))*(COUNTIFS(Inputs!$Q$2:$Q$156,"A06|"&$A3,Inputs!$I$2:$I$156,"<>"))*(COUNTIFS(Inputs!$Q$2:$Q$156,"A07|"&$A3,Inputs!$I$2:$I$156,"<>"))=0,"PENDING",IF(ABS(SUMIFS(Inputs!$J$2:$J$156,Inputs!$Q$2:$Q$156,"A06|"&$A3)/SUMIFS(Inputs!$J$2:$J$156,Inputs!$Q$2:$Q$156,"A05|"&$A3)*100-SUMIFS(Inputs!$J$2:$J$156,Inputs!$Q$2:$Q$156,"A07|"&$A3))<=0.2,"OK","CHECK")) -> OK | D3: =IF((COUNTIFS(Inputs!$Q$2:$Q$156,"A12|"&$A3,Inputs!$I$2:$I$156,"<>"))*(COUNTIFS(Inputs!$Q$2:$Q$156,"A09|"&$A3,Inputs!$I$2:$I$156,"<>"))*(COUNTIFS(Inputs!$Q$2:$Q$156,"A11|"&$A3,Inputs!$I$2:$I$156,"<>"))=0,"PENDING",IF(ABS(SUMIFS(Inputs!$J$2:$J$156,Inputs!$Q$2:$Q$156,"A12|"&$A3)-SUMIFS(Inputs!$J$2:$J$156,Inputs!$Q$2:$Q$156,"A09|"&$A3)-SUMIFS(Inputs!$J$2:$J$156,Inputs!$Q$2:$Q$156,"A11|"&$A3))<=2,"OK","CHECK")) -> OK | E3: =IF((COUNTIFS(Inputs!$Q$2:$Q$156,"A03|"&$A3,Inputs!$I$2:$I$156,"<>"))*(COUNTIFS(Inputs!$Q$2:$Q$156,"A02|"&$A3,Inputs!$I$2:$I$156,"<>"))*(COUNTIFS(Inputs!$Q$2:$Q$156,"A12|"&$A3,Inputs!$I$2:$I$156,"<>"))=0,"PENDING",IF(ABS(SUMIFS(Inputs!$J$2:$J$156,Inputs!$Q$2:$Q$156,"A03|"&$A3)-SUMIFS(Inputs!$J$2:$J$156,Inputs!$Q$2:$Q$156,"A02|"&$A3)-SUMIFS(Inputs!$J$2:$J$156,Inputs!$Q$2:$Q$156,"A12|"&$A3))<=60,"OK","CHECK")) -> OK | F3: =IF((COUNTIFS(Inputs!$Q$2:$Q$156,"A03|"&$A3,Inputs!$I$2:$I$156,"<>"))*(COUNTIFS(Inputs!$Q$2:$Q$156,"A01|"&$A3,Inputs!$I$2:$I$156,"<>"))*(COUNTIFS(Inputs!$Q$2:$Q$156,"A04|"&$A3,Inputs!$I$2:$I$156,"<>"))=0,"PENDING",IF(ABS(SUMIFS(Inputs!$J$2:$J$156,Inputs!$Q$2:$Q$156,"A03|"&$A3)/SUMIFS(Inputs!$J$2:$J$156,Inputs!$Q$2:$Q$156,"A01|"&$A3)*100-SUMIFS(Inputs!$J$2:$J$156,Inputs!$Q$2:$Q$156,"A04|"&$A3))<=0.15,"OK","CHECK")) -> OK | G3: =IF((COUNTIFS(Inputs!$Q$2:$Q$156,"A01|"&$A3,Inputs!$I$2:$I$156,"<>"))*(COUNTIFS(Inputs!$Q$2:$Q$156,"O06|"&$A3,Inputs!$I$2:$I$156,"<>"))=0,IF(COUNTIFS(Inputs!$Q$2:$Q$156,"O06|"&$A3,Inputs!$I$2:$I$156,"",Inputs!$P$2:$P$156,"<>")>0,"N/A (blank - see Inputs note)","PENDING"),IF(ABS(SUMIFS(Inputs!$J$2:$J$156,Inputs!$Q$2:$Q$156,"A01|"&$A3)*1000/INDEX(FS_Reference!$D$2:$D$10,MATCH($A3,FS_Reference!$A$2:$A$10,0))-SUMIFS(Inputs!$J$2:$J$156,Inputs!$Q$2:$Q$156,"O06|"&$A3))<=1.5,"OK","CHECK")) -> OK | H3: =IF((COUNTIFS(Inputs!$Q$2:$Q$156,"B01|"&$A3,Inputs!$I$2:$I$156,"<>"))*(COUNTIFS(Inputs!$Q$2:$Q$156,"B02|"&$A3,Inputs!$I$2:$I$156,"<>"))*(COUNTIFS(Inputs!$Q$2:$Q$156,"B03|"&$A3,Inputs!$I$2:$I$156,"<>"))*(COUNTIFS(Inputs!$Q$2:$Q$156,"B04|"&$A3,Inputs!$I$2:$I$156,"<>"))=0,"PENDING",IF(ABS(INDEX(FS_Reference!$C$2:$C$10,MATCH("FY_2022",FS_Reference!$A$2:$A$10,0))+SUMIFS(Inputs!$J$2:$J$156,Inputs!$Q$2:$Q$156,"B01|"&$A3)+SUMIFS(Inputs!$J$2:$J$156,Inputs!$Q$2:$Q$156,"B02|"&$A3)+SUMIFS(Inputs!$J$2:$J$156,Inputs!$Q$2:$Q$156,"B03|"&$A3)+SUMIFS(Inputs!$J$2:$J$156,Inputs!$Q$2:$Q$156,"B04|"&$A3)-INDEX(FS_Reference!$C$2:$C$10,MATCH($A3,FS_Reference!$A$2:$A$10,0)))<=$L3,"OK","CHECK")) -> OK | I3: =IF(COUNTIFS(Inputs!$Q$2:$Q$156,"B03|"&$A3,Inputs!$I$2:$I$156,"<>")=0,"PENDING",IF(ABS(INDEX(FS_Reference!$H$2:$H$10,MATCH($A3,FS_Reference!$A$2:$A$10,0))-INDEX(FS_Reference!$H$2:$H$10,MATCH("FY_2022",FS_Reference!$A$2:$A$10,0))-SUMIFS(Inputs!$J$2:$J$156,Inputs!$Q$2:$Q$156,"B03|"&$A3))<=$L3/2,"OK","CHECK")) -> OK | J3: =IF(COUNTIFS(Inputs!$Q$2:$Q$156,"B04|"&$A3,Inputs!$I$2:$I$156,"<>")=0,"PENDING",IF(ABS(INDEX(FS_Reference!$I$2:$I$10,MATCH($A3,FS_Reference!$A$2:$A$10,0))-INDEX(FS_Reference!$I$2:$I$10,MATCH("FY_2022",FS_Reference!$A$2:$A$10,0))-SUMIFS(Inputs!$J$2:$J$156,Inputs!$Q$2:$Q$156,"B04|"&$A3))<=$L3/2,"OK","CHECK")) -> OK | K3: =IF((COUNTIFS(Inputs!$Q$2:$Q$156,"B01|"&$A3,Inputs!$I$2:$I$156,"<>"))*(COUNTIFS(Inputs!$Q$2:$Q$156,"B02|"&$A3,Inputs!$I$2:$I$156,"<>"))=0,"PENDING",IF(ABS(INDEX(FS_Reference!$G$2:$G$10,MATCH($A3,FS_Reference!$A$2:$A$10,0))-INDEX(FS_Reference!$G$2:$G$10,MATCH("FY_2022",FS_Reference!$A$2:$A$10,0))-SUMIFS(Inputs!$J$2:$J$156,Inputs!$Q$2:$Q$156,"B01|"&$A3)-SUMIFS(Inputs!$J$2:$J$156,Inputs!$Q$2:$Q$156,"B02|"&$A3))<=$L3,"OK","CHECK")) -> OK | L3: 250 | M3: =COUNTIFS(Inputs!$D$2:$D$156,$A3,Inputs!$I$2:$I$156,"<>") -> 21 | N3: =COUNTIFS(Inputs!$D$2:$D$156,$A3,Inputs!$I$2:$I$156,"",Inputs!$P$2:$P$156,"<>") -> 0 | O3: =COUNTIFS(Inputs!$D$2:$D$156,$A3) -> 21
A4: H1_2024 | B4: =IF((COUNTIFS(Inputs!$Q$2:$Q$156,"A05|"&$A4,Inputs!$I$2:$I$156,"<>"))*(COUNTIFS(Inputs!$Q$2:$Q$156,"A06|"&$A4,Inputs!$I$2:$I$156,"<>"))*(COUNTIFS(Inputs!$Q$2:$Q$156,"A08|"&$A4,Inputs!$I$2:$I$156,"<>"))=0,"PENDING",IF(ABS(SUMIFS(Inputs!$J$2:$J$156,Inputs!$Q$2:$Q$156,"A05|"&$A4)-SUMIFS(Inputs!$J$2:$J$156,Inputs!$Q$2:$Q$156,"A06|"&$A4)-SUMIFS(Inputs!$J$2:$J$156,Inputs!$Q$2:$Q$156,"A08|"&$A4))<=2,"OK","CHECK")) -> OK | C4: =IF((COUNTIFS(Inputs!$Q$2:$Q$156,"A05|"&$A4,Inputs!$I$2:$I$156,"<>"))*(COUNTIFS(Inputs!$Q$2:$Q$156,"A06|"&$A4,Inputs!$I$2:$I$156,"<>"))*(COUNTIFS(Inputs!$Q$2:$Q$156,"A07|"&$A4,Inputs!$I$2:$I$156,"<>"))=0,"PENDING",IF(ABS(SUMIFS(Inputs!$J$2:$J$156,Inputs!$Q$2:$Q$156,"A06|"&$A4)/SUMIFS(Inputs!$J$2:$J$156,Inputs!$Q$2:$Q$156,"A05|"&$A4)*100-SUMIFS(Inputs!$J$2:$J$156,Inputs!$Q$2:$Q$156,"A07|"&$A4))<=0.2,"OK","CHECK")) -> OK | D4: =IF((COUNTIFS(Inputs!$Q$2:$Q$156,"A12|"&$A4,Inputs!$I$2:$I$156,"<>"))*(COUNTIFS(Inputs!$Q$2:$Q$156,"A09|"&$A4,Inputs!$I$2:$I$156,"<>"))*(COUNTIFS(Inputs!$Q$2:$Q$156,"A11|"&$A4,Inputs!$I$2:$I$156,"<>"))=0,"PENDING",IF(ABS(SUMIFS(Inputs!$J$2:$J$156,Inputs!$Q$2:$Q$156,"A12|"&$A4)-SUMIFS(Inputs!$J$2:$J$156,Inputs!$Q$2:$Q$156,"A09|"&$A4)-SUMIFS(Inputs!$J$2:$J$156,Inputs!$Q$2:$Q$156,"A11|"&$A4))<=2,"OK","CHECK")) -> OK | E4: =IF((COUNTIFS(Inputs!$Q$2:$Q$156,"A03|"&$A4,Inputs!$I$2:$I$156,"<>"))*(COUNTIFS(Inputs!$Q$2:$Q$156,"A02|"&$A4,Inputs!$I$2:$I$156,"<>"))*(COUNTIFS(Inputs!$Q$2:$Q$156,"A12|"&$A4,Inputs!$I$2:$I$156,"<>"))=0,"PENDING",IF(ABS(SUMIFS(Inputs!$J$2:$J$156,Inputs!$Q$2:$Q$156,"A03|"&$A4)-SUMIFS(Inputs!$J$2:$J$156,Inputs!$Q$2:$Q$156,"A02|"&$A4)-SUMIFS(Inputs!$J$2:$J$156,Inputs!$Q$2:$Q$156,"A12|"&$A4))<=60,"OK","CHECK")) -> OK | F4: =IF((COUNTIFS(Inputs!$Q$2:$Q$156,"A03|"&$A4,Inputs!$I$2:$I$156,"<>"))*(COUNTIFS(Inputs!$Q$2:$Q$156,"A01|"&$A4,Inputs!$I$2:$I$156,"<>"))*(COUNTIFS(Inputs!$Q$2:$Q$156,"A04|"&$A4,Inputs!$I$2:$I$156,"<>"))=0,"PENDING",IF(ABS(SUMIFS(Inputs!$J$2:$J$156,Inputs!$Q$2:$Q$156,"A03|"&$A4)/SUMIFS(Inputs!$J$2:$J$156,Inputs!$Q$2:$Q$156,"A01|"&$A4)*100-SUMIFS(Inputs!$J$2:$J$156,Inputs!$Q$2:$Q$156,"A04|"&$A4))<=0.15,"OK","CHECK")) -> OK | G4: =IF((COUNTIFS(Inputs!$Q$2:$Q$156,"A01|"&$A4,Inputs!$I$2:$I$156,"<>"))*(COUNTIFS(Inputs!$Q$2:$Q$156,"O06|"&$A4,Inputs!$I$2:$I$156,"<>"))=0,IF(COUNTIFS(Inputs!$Q$2:$Q$156,"O06|"&$A4,Inputs!$I$2:$I$156,"",Inputs!$P$2:$P$156,"<>")>0,"N/A (blank - see Inputs note)","PENDING"),IF(ABS(SUMIFS(Inputs!$J$2:$J$156,Inputs!$Q$2:$Q$156,"A01|"&$A4)*1000/INDEX(FS_Reference!$D$2:$D$10,MATCH($A4,FS_Reference!$A$2:$A$10,0))-SUMIFS(Inputs!$J$2:$J$156,Inputs!$Q$2:$Q$156,"O06|"&$A4))<=1.5,"OK","CHECK")) -> OK | H4: =IF((COUNTIFS(Inputs!$Q$2:$Q$156,"B01|"&$A4,Inputs!$I$2:$I$156,"<>"))*(COUNTIFS(Inputs!$Q$2:$Q$156,"B02|"&$A4,Inputs!$I$2:$I$156,"<>"))*(COUNTIFS(Inputs!$Q$2:$Q$156,"B03|"&$A4,Inputs!$I$2:$I$156,"<>"))*(COUNTIFS(Inputs!$Q$2:$Q$156,"B04|"&$A4,Inputs!$I$2:$I$156,"<>"))=0,"PENDING",IF(ABS(INDEX(FS_Reference!$C$2:$C$10,MATCH("H1_2023",FS_Reference!$A$2:$A$10,0))+SUMIFS(Inputs!$J$2:$J$156,Inputs!$Q$2:$Q$156,"B01|"&$A4)+SUMIFS(Inputs!$J$2:$J$156,Inputs!$Q$2:$Q$156,"B02|"&$A4)+SUMIFS(Inputs!$J$2:$J$156,Inputs!$Q$2:$Q$156,"B03|"&$A4)+SUMIFS(Inputs!$J$2:$J$156,Inputs!$Q$2:$Q$156,"B04|"&$A4)-INDEX(FS_Reference!$C$2:$C$10,MATCH($A4,FS_Reference!$A$2:$A$10,0)))<=$L4,"OK","CHECK")) -> OK | I4: =IF(COUNTIFS(Inputs!$Q$2:$Q$156,"B03|"&$A4,Inputs!$I$2:$I$156,"<>")=0,"PENDING",IF(ABS(INDEX(FS_Reference!$H$2:$H$10,MATCH($A4,FS_Reference!$A$2:$A$10,0))-INDEX(FS_Reference!$H$2:$H$10,MATCH("H1_2023",FS_Reference!$A$2:$A$10,0))-SUMIFS(Inputs!$J$2:$J$156,Inputs!$Q$2:$Q$156,"B03|"&$A4))<=$L4/2,"OK","CHECK")) -> OK | J4: =IF(COUNTIFS(Inputs!$Q$2:$Q$156,"B04|"&$A4,Inputs!$I$2:$I$156,"<>")=0,"PENDING",IF(ABS(INDEX(FS_Reference!$I$2:$I$10,MATCH($A4,FS_Reference!$A$2:$A$10,0))-INDEX(FS_Reference!$I$2:$I$10,MATCH("H1_2023",FS_Reference!$A$2:$A$10,0))-SUMIFS(Inputs!$J$2:$J$156,Inputs!$Q$2:$Q$156,"B04|"&$A4))<=$L4/2,"OK","CHECK")) -> OK | K4: =IF((COUNTIFS(Inputs!$Q$2:$Q$156,"B01|"&$A4,Inputs!$I$2:$I$156,"<>"))*(COUNTIFS(Inputs!$Q$2:$Q$156,"B02|"&$A4,Inputs!$I$2:$I$156,"<>"))=0,"PENDING",IF(ABS(INDEX(FS_Reference!$G$2:$G$10,MATCH($A4,FS_Reference!$A$2:$A$10,0))-INDEX(FS_Reference!$G$2:$G$10,MATCH("H1_2023",FS_Reference!$A$2:$A$10,0))-SUMIFS(Inputs!$J$2:$J$156,Inputs!$Q$2:$Q$156,"B01|"&$A4)-SUMIFS(Inputs!$J$2:$J$156,Inputs!$Q$2:$Q$156,"B02|"&$A4))<=$L4,"OK","CHECK")) -> OK | L4: 50 | M4: =COUNTIFS(Inputs!$D$2:$D$156,$A4,Inputs!$I$2:$I$156,"<>") -> 21 | N4: =COUNTIFS(Inputs!$D$2:$D$156,$A4,Inputs!$I$2:$I$156,"",Inputs!$P$2:$P$156,"<>") -> 0 | O4: =COUNTIFS(Inputs!$D$2:$D$156,$A4) -> 21
A5: FY_2024 | B5: =IF((COUNTIFS(Inputs!$Q$2:$Q$156,"A05|"&$A5,Inputs!$I$2:$I$156,"<>"))*(COUNTIFS(Inputs!$Q$2:$Q$156,"A06|"&$A5,Inputs!$I$2:$I$156,"<>"))*(COUNTIFS(Inputs!$Q$2:$Q$156,"A08|"&$A5,Inputs!$I$2:$I$156,"<>"))=0,"PENDING",IF(ABS(SUMIFS(Inputs!$J$2:$J$156,Inputs!$Q$2:$Q$156,"A05|"&$A5)-SUMIFS(Inputs!$J$2:$J$156,Inputs!$Q$2:$Q$156,"A06|"&$A5)-SUMIFS(Inputs!$J$2:$J$156,Inputs!$Q$2:$Q$156,"A08|"&$A5))<=2,"OK","CHECK")) -> OK | C5: =IF((COUNTIFS(Inputs!$Q$2:$Q$156,"A05|"&$A5,Inputs!$I$2:$I$156,"<>"))*(COUNTIFS(Inputs!$Q$2:$Q$156,"A06|"&$A5,Inputs!$I$2:$I$156,"<>"))*(COUNTIFS(Inputs!$Q$2:$Q$156,"A07|"&$A5,Inputs!$I$2:$I$156,"<>"))=0,"PENDING",IF(ABS(SUMIFS(Inputs!$J$2:$J$156,Inputs!$Q$2:$Q$156,"A06|"&$A5)/SUMIFS(Inputs!$J$2:$J$156,Inputs!$Q$2:$Q$156,"A05|"&$A5)*100-SUMIFS(Inputs!$J$2:$J$156,Inputs!$Q$2:$Q$156,"A07|"&$A5))<=0.2,"OK","CHECK")) -> OK | D5: =IF((COUNTIFS(Inputs!$Q$2:$Q$156,"A12|"&$A5,Inputs!$I$2:$I$156,"<>"))*(COUNTIFS(Inputs!$Q$2:$Q$156,"A09|"&$A5,Inputs!$I$2:$I$156,"<>"))*(COUNTIFS(Inputs!$Q$2:$Q$156,"A11|"&$A5,Inputs!$I$2:$I$156,"<>"))=0,"PENDING",IF(ABS(SUMIFS(Inputs!$J$2:$J$156,Inputs!$Q$2:$Q$156,"A12|"&$A5)-SUMIFS(Inputs!$J$2:$J$156,Inputs!$Q$2:$Q$156,"A09|"&$A5)-SUMIFS(Inputs!$J$2:$J$156,Inputs!$Q$2:$Q$156,"A11|"&$A5))<=2,"OK","CHECK")) -> OK | E5: =IF((COUNTIFS(Inputs!$Q$2:$Q$156,"A03|"&$A5,Inputs!$I$2:$I$156,"<>"))*(COUNTIFS(Inputs!$Q$2:$Q$156,"A02|"&$A5,Inputs!$I$2:$I$156,"<>"))*(COUNTIFS(Inputs!$Q$2:$Q$156,"A12|"&$A5,Inputs!$I$2:$I$156,"<>"))=0,"PENDING",IF(ABS(SUMIFS(Inputs!$J$2:$J$156,Inputs!$Q$2:$Q$156,"A03|"&$A5)-SUMIFS(Inputs!$J$2:$J$156,Inputs!$Q$2:$Q$156,"A02|"&$A5)-SUMIFS(Inputs!$J$2:$J$156,Inputs!$Q$2:$Q$156,"A12|"&$A5))<=60,"OK","CHECK")) -> OK | F5: =IF((COUNTIFS(Inputs!$Q$2:$Q$156,"A03|"&$A5,Inputs!$I$2:$I$156,"<>"))*(COUNTIFS(Inputs!$Q$2:$Q$156,"A01|"&$A5,Inputs!$I$2:$I$156,"<>"))*(COUNTIFS(Inputs!$Q$2:$Q$156,"A04|"&$A5,Inputs!$I$2:$I$156,"<>"))=0,"PENDING",IF(ABS(SUMIFS(Inputs!$J$2:$J$156,Inputs!$Q$2:$Q$156,"A03|"&$A5)/SUMIFS(Inputs!$J$2:$J$156,Inputs!$Q$2:$Q$156,"A01|"&$A5)*100-SUMIFS(Inputs!$J$2:$J$156,Inputs!$Q$2:$Q$156,"A04|"&$A5))<=0.15,"OK","CHECK")) -> OK | G5: =IF((COUNTIFS(Inputs!$Q$2:$Q$156,"A01|"&$A5,Inputs!$I$2:$I$156,"<>"))*(COUNTIFS(Inputs!$Q$2:$Q$156,"O06|"&$A5,Inputs!$I$2:$I$156,"<>"))=0,IF(COUNTIFS(Inputs!$Q$2:$Q$156,"O06|"&$A5,Inputs!$I$2:$I$156,"",Inputs!$P$2:$P$156,"<>")>0,"N/A (blank - see Inputs note)","PENDING"),IF(ABS(SUMIFS(Inputs!$J$2:$J$156,Inputs!$Q$2:$Q$156,"A01|"&$A5)*1000/INDEX(FS_Reference!$D$2:$D$10,MATCH($A5,FS_Reference!$A$2:$A$10,0))-SUMIFS(Inputs!$J$2:$J$156,Inputs!$Q$2:$Q$156,"O06|"&$A5))<=1.5,"OK","CHECK")) -> OK | H5: =IF((COUNTIFS(Inputs!$Q$2:$Q$156,"B01|"&$A5,Inputs!$I$2:$I$156,"<>"))*(COUNTIFS(Inputs!$Q$2:$Q$156,"B02|"&$A5,Inputs!$I$2:$I$156,"<>"))*(COUNTIFS(Inputs!$Q$2:$Q$156,"B03|"&$A5,Inputs!$I$2:$I$156,"<>"))*(COUNTIFS(Inputs!$Q$2:$Q$156,"B04|"&$A5,Inputs!$I$2:$I$156,"<>"))=0,"PENDING",IF(ABS(INDEX(FS_Reference!$C$2:$C$10,MATCH("FY_2023",FS_Reference!$A$2:$A$10,0))+SUMIFS(Inputs!$J$2:$J$156,Inputs!$Q$2:$Q$156,"B01|"&$A5)+SUMIFS(Inputs!$J$2:$J$156,Inputs!$Q$2:$Q$156,"B02|"&$A5)+SUMIFS(Inputs!$J$2:$J$156,Inputs!$Q$2:$Q$156,"B03|"&$A5)+SUMIFS(Inputs!$J$2:$J$156,Inputs!$Q$2:$Q$156,"B04|"&$A5)-INDEX(FS_Reference!$C$2:$C$10,MATCH($A5,FS_Reference!$A$2:$A$10,0)))<=$L5,"OK","CHECK")) -> OK | I5: =IF(COUNTIFS(Inputs!$Q$2:$Q$156,"B03|"&$A5,Inputs!$I$2:$I$156,"<>")=0,"PENDING",IF(ABS(INDEX(FS_Reference!$H$2:$H$10,MATCH($A5,FS_Reference!$A$2:$A$10,0))-INDEX(FS_Reference!$H$2:$H$10,MATCH("FY_2023",FS_Reference!$A$2:$A$10,0))-SUMIFS(Inputs!$J$2:$J$156,Inputs!$Q$2:$Q$156,"B03|"&$A5))<=$L5/2,"OK","CHECK")) -> OK | J5: =IF(COUNTIFS(Inputs!$Q$2:$Q$156,"B04|"&$A5,Inputs!$I$2:$I$156,"<>")=0,"PENDING",IF(ABS(INDEX(FS_Reference!$I$2:$I$10,MATCH($A5,FS_Reference!$A$2:$A$10,0))-INDEX(FS_Reference!$I$2:$I$10,MATCH("FY_2023",FS_Reference!$A$2:$A$10,0))-SUMIFS(Inputs!$J$2:$J$156,Inputs!$Q$2:$Q$156,"B04|"&$A5))<=$L5/2,"OK","CHECK")) -> OK | K5: =IF((COUNTIFS(Inputs!$Q$2:$Q$156,"B01|"&$A5,Inputs!$I$2:$I$156,"<>"))*(COUNTIFS(Inputs!$Q$2:$Q$156,"B02|"&$A5,Inputs!$I$2:$I$156,"<>"))=0,"PENDING",IF(ABS(INDEX(FS_Reference!$G$2:$G$10,MATCH($A5,FS_Reference!$A$2:$A$10,0))-INDEX(FS_Reference!$G$2:$G$10,MATCH("FY_2023",FS_Reference!$A$2:$A$10,0))-SUMIFS(Inputs!$J$2:$J$156,Inputs!$Q$2:$Q$156,"B01|"&$A5)-SUMIFS(Inputs!$J$2:$J$156,Inputs!$Q$2:$Q$156,"B02|"&$A5))<=$L5,"OK","CHECK")) -> OK | L5: 250 | M5: =COUNTIFS(Inputs!$D$2:$D$156,$A5,Inputs!$I$2:$I$156,"<>") -> 21 | N5: =COUNTIFS(Inputs!$D$2:$D$156,$A5,Inputs!$I$2:$I$156,"",Inputs!$P$2:$P$156,"<>") -> 0 | O5: =COUNTIFS(Inputs!$D$2:$D$156,$A5) -> 21
A6: H1_2025 | B6: =IF((COUNTIFS(Inputs!$Q$2:$Q$156,"A05|"&$A6,Inputs!$I$2:$I$156,"<>"))*(COUNTIFS(Inputs!$Q$2:$Q$156,"A06|"&$A6,Inputs!$I$2:$I$156,"<>"))*(COUNTIFS(Inputs!$Q$2:$Q$156,"A08|"&$A6,Inputs!$I$2:$I$156,"<>"))=0,"PENDING",IF(ABS(SUMIFS(Inputs!$J$2:$J$156,Inputs!$Q$2:$Q$156,"A05|"&$A6)-SUMIFS(Inputs!$J$2:$J$156,Inputs!$Q$2:$Q$156,"A06|"&$A6)-SUMIFS(Inputs!$J$2:$J$156,Inputs!$Q$2:$Q$156,"A08|"&$A6))<=2,"OK","CHECK")) -> OK | C6: =IF((COUNTIFS(Inputs!$Q$2:$Q$156,"A05|"&$A6,Inputs!$I$2:$I$156,"<>"))*(COUNTIFS(Inputs!$Q$2:$Q$156,"A06|"&$A6,Inputs!$I$2:$I$156,"<>"))*(COUNTIFS(Inputs!$Q$2:$Q$156,"A07|"&$A6,Inputs!$I$2:$I$156,"<>"))=0,"PENDING",IF(ABS(SUMIFS(Inputs!$J$2:$J$156,Inputs!$Q$2:$Q$156,"A06|"&$A6)/SUMIFS(Inputs!$J$2:$J$156,Inputs!$Q$2:$Q$156,"A05|"&$A6)*100-SUMIFS(Inputs!$J$2:$J$156,Inputs!$Q$2:$Q$156,"A07|"&$A6))<=0.2,"OK","CHECK")) -> OK | D6: =IF((COUNTIFS(Inputs!$Q$2:$Q$156,"A12|"&$A6,Inputs!$I$2:$I$156,"<>"))*(COUNTIFS(Inputs!$Q$2:$Q$156,"A09|"&$A6,Inputs!$I$2:$I$156,"<>"))*(COUNTIFS(Inputs!$Q$2:$Q$156,"A11|"&$A6,Inputs!$I$2:$I$156,"<>"))=0,"PENDING",IF(ABS(SUMIFS(Inputs!$J$2:$J$156,Inputs!$Q$2:$Q$156,"A12|"&$A6)-SUMIFS(Inputs!$J$2:$J$156,Inputs!$Q$2:$Q$156,"A09|"&$A6)-SUMIFS(Inputs!$J$2:$J$156,Inputs!$Q$2:$Q$156,"A11|"&$A6))<=2,"OK","CHECK")) -> OK | E6: =IF((COUNTIFS(Inputs!$Q$2:$Q$156,"A03|"&$A6,Inputs!$I$2:$I$156,"<>"))*(COUNTIFS(Inputs!$Q$2:$Q$156,"A02|"&$A6,Inputs!$I$2:$I$156,"<>"))*(COUNTIFS(Inputs!$Q$2:$Q$156,"A12|"&$A6,Inputs!$I$2:$I$156,"<>"))=0,"PENDING",IF(ABS(SUMIFS(Inputs!$J$2:$J$156,Inputs!$Q$2:$Q$156,"A03|"&$A6)-SUMIFS(Inputs!$J$2:$J$156,Inputs!$Q$2:$Q$156,"A02|"&$A6)-SUMIFS(Inputs!$J$2:$J$156,Inputs!$Q$2:$Q$156,"A12|"&$A6))<=60,"OK","CHECK")) -> OK | F6: =IF((COUNTIFS(Inputs!$Q$2:$Q$156,"A03|"&$A6,Inputs!$I$2:$I$156,"<>"))*(COUNTIFS(Inputs!$Q$2:$Q$156,"A01|"&$A6,Inputs!$I$2:$I$156,"<>"))*(COUNTIFS(Inputs!$Q$2:$Q$156,"A04|"&$A6,Inputs!$I$2:$I$156,"<>"))=0,"PENDING",IF(ABS(SUMIFS(Inputs!$J$2:$J$156,Inputs!$Q$2:$Q$156,"A03|"&$A6)/SUMIFS(Inputs!$J$2:$J$156,Inputs!$Q$2:$Q$156,"A01|"&$A6)*100-SUMIFS(Inputs!$J$2:$J$156,Inputs!$Q$2:$Q$156,"A04|"&$A6))<=0.15,"OK","CHECK")) -> OK | G6: =IF((COUNTIFS(Inputs!$Q$2:$Q$156,"A01|"&$A6,Inputs!$I$2:$I$156,"<>"))*(COUNTIFS(Inputs!$Q$2:$Q$156,"O06|"&$A6,Inputs!$I$2:$I$156,"<>"))=0,IF(COUNTIFS(Inputs!$Q$2:$Q$156,"O06|"&$A6,Inputs!$I$2:$I$156,"",Inputs!$P$2:$P$156,"<>")>0,"N/A (blank - see Inputs note)","PENDING"),IF(ABS(SUMIFS(Inputs!$J$2:$J$156,Inputs!$Q$2:$Q$156,"A01|"&$A6)*1000/INDEX(FS_Reference!$D$2:$D$10,MATCH($A6,FS_Reference!$A$2:$A$10,0))-SUMIFS(Inputs!$J$2:$J$156,Inputs!$Q$2:$Q$156,"O06|"&$A6))<=1.5,"OK","CHECK")) -> OK | H6: =IF((COUNTIFS(Inputs!$Q$2:$Q$156,"B01|"&$A6,Inputs!$I$2:$I$156,"<>"))*(COUNTIFS(Inputs!$Q$2:$Q$156,"B02|"&$A6,Inputs!$I$2:$I$156,"<>"))*(COUNTIFS(Inputs!$Q$2:$Q$156,"B03|"&$A6,Inputs!$I$2:$I$156,"<>"))*(COUNTIFS(Inputs!$Q$2:$Q$156,"B04|"&$A6,Inputs!$I$2:$I$156,"<>"))=0,"PENDING",IF(ABS(INDEX(FS_Reference!$C$2:$C$10,MATCH("H1_2024",FS_Reference!$A$2:$A$10,0))+SUMIFS(Inputs!$J$2:$J$156,Inputs!$Q$2:$Q$156,"B01|"&$A6)+SUMIFS(Inputs!$J$2:$J$156,Inputs!$Q$2:$Q$156,"B02|"&$A6)+SUMIFS(Inputs!$J$2:$J$156,Inputs!$Q$2:$Q$156,"B03|"&$A6)+SUMIFS(Inputs!$J$2:$J$156,Inputs!$Q$2:$Q$156,"B04|"&$A6)-INDEX(FS_Reference!$C$2:$C$10,MATCH($A6,FS_Reference!$A$2:$A$10,0)))<=$L6,"OK","CHECK")) -> OK | I6: =IF(COUNTIFS(Inputs!$Q$2:$Q$156,"B03|"&$A6,Inputs!$I$2:$I$156,"<>")=0,"PENDING",IF(ABS(INDEX(FS_Reference!$H$2:$H$10,MATCH($A6,FS_Reference!$A$2:$A$10,0))-INDEX(FS_Reference!$H$2:$H$10,MATCH("H1_2024",FS_Reference!$A$2:$A$10,0))-SUMIFS(Inputs!$J$2:$J$156,Inputs!$Q$2:$Q$156,"B03|"&$A6))<=$L6/2,"OK","CHECK")) -> OK | J6: =IF(COUNTIFS(Inputs!$Q$2:$Q$156,"B04|"&$A6,Inputs!$I$2:$I$156,"<>")=0,"PENDING",IF(ABS(INDEX(FS_Reference!$I$2:$I$10,MATCH($A6,FS_Reference!$A$2:$A$10,0))-INDEX(FS_Reference!$I$2:$I$10,MATCH("H1_2024",FS_Reference!$A$2:$A$10,0))-SUMIFS(Inputs!$J$2:$J$156,Inputs!$Q$2:$Q$156,"B04|"&$A6))<=$L6/2,"OK","CHECK")) -> OK | K6: =IF((COUNTIFS(Inputs!$Q$2:$Q$156,"B01|"&$A6,Inputs!$I$2:$I$156,"<>"))*(COUNTIFS(Inputs!$Q$2:$Q$156,"B02|"&$A6,Inputs!$I$2:$I$156,"<>"))=0,"PENDING",IF(ABS(INDEX(FS_Reference!$G$2:$G$10,MATCH($A6,FS_Reference!$A$2:$A$10,0))-INDEX(FS_Reference!$G$2:$G$10,MATCH("H1_2024",FS_Reference!$A$2:$A$10,0))-SUMIFS(Inputs!$J$2:$J$156,Inputs!$Q$2:$Q$156,"B01|"&$A6)-SUMIFS(Inputs!$J$2:$J$156,Inputs!$Q$2:$Q$156,"B02|"&$A6))<=$L6,"OK","CHECK")) -> OK | L6: 50 | M6: =COUNTIFS(Inputs!$D$2:$D$156,$A6,Inputs!$I$2:$I$156,"<>") -> 25 | N6: =COUNTIFS(Inputs!$D$2:$D$156,$A6,Inputs!$I$2:$I$156,"",Inputs!$P$2:$P$156,"<>") -> 0 | O6: =COUNTIFS(Inputs!$D$2:$D$156,$A6) -> 25
A7: FY_2025 | B7: =IF((COUNTIFS(Inputs!$Q$2:$Q$156,"A05|"&$A7,Inputs!$I$2:$I$156,"<>"))*(COUNTIFS(Inputs!$Q$2:$Q$156,"A06|"&$A7,Inputs!$I$2:$I$156,"<>"))*(COUNTIFS(Inputs!$Q$2:$Q$156,"A08|"&$A7,Inputs!$I$2:$I$156,"<>"))=0,"PENDING",IF(ABS(SUMIFS(Inputs!$J$2:$J$156,Inputs!$Q$2:$Q$156,"A05|"&$A7)-SUMIFS(Inputs!$J$2:$J$156,Inputs!$Q$2:$Q$156,"A06|"&$A7)-SUMIFS(Inputs!$J$2:$J$156,Inputs!$Q$2:$Q$156,"A08|"&$A7))<=2,"OK","CHECK")) -> OK | C7: =IF((COUNTIFS(Inputs!$Q$2:$Q$156,"A05|"&$A7,Inputs!$I$2:$I$156,"<>"))*(COUNTIFS(Inputs!$Q$2:$Q$156,"A06|"&$A7,Inputs!$I$2:$I$156,"<>"))*(COUNTIFS(Inputs!$Q$2:$Q$156,"A07|"&$A7,Inputs!$I$2:$I$156,"<>"))=0,"PENDING",IF(ABS(SUMIFS(Inputs!$J$2:$J$156,Inputs!$Q$2:$Q$156,"A06|"&$A7)/SUMIFS(Inputs!$J$2:$J$156,Inputs!$Q$2:$Q$156,"A05|"&$A7)*100-SUMIFS(Inputs!$J$2:$J$156,Inputs!$Q$2:$Q$156,"A07|"&$A7))<=0.2,"OK","CHECK")) -> OK | D7: =IF((COUNTIFS(Inputs!$Q$2:$Q$156,"A12|"&$A7,Inputs!$I$2:$I$156,"<>"))*(COUNTIFS(Inputs!$Q$2:$Q$156,"A09|"&$A7,Inputs!$I$2:$I$156,"<>"))*(COUNTIFS(Inputs!$Q$2:$Q$156,"A11|"&$A7,Inputs!$I$2:$I$156,"<>"))=0,"PENDING",IF(ABS(SUMIFS(Inputs!$J$2:$J$156,Inputs!$Q$2:$Q$156,"A12|"&$A7)-SUMIFS(Inputs!$J$2:$J$156,Inputs!$Q$2:$Q$156,"A09|"&$A7)-SUMIFS(Inputs!$J$2:$J$156,Inputs!$Q$2:$Q$156,"A11|"&$A7))<=2,"OK","CHECK")) -> OK | E7: =IF((COUNTIFS(Inputs!$Q$2:$Q$156,"A03|"&$A7,Inputs!$I$2:$I$156,"<>"))*(COUNTIFS(Inputs!$Q$2:$Q$156,"A02|"&$A7,Inputs!$I$2:$I$156,"<>"))*(COUNTIFS(Inputs!$Q$2:$Q$156,"A12|"&$A7,Inputs!$I$2:$I$156,"<>"))=0,"PENDING",IF(ABS(SUMIFS(Inputs!$J$2:$J$156,Inputs!$Q$2:$Q$156,"A03|"&$A7)-SUMIFS(Inputs!$J$2:$J$156,Inputs!$Q$2:$Q$156,"A02|"&$A7)-SUMIFS(Inputs!$J$2:$J$156,Inputs!$Q$2:$Q$156,"A12|"&$A7))<=60,"OK","CHECK")) -> OK | F7: =IF((COUNTIFS(Inputs!$Q$2:$Q$156,"A03|"&$A7,Inputs!$I$2:$I$156,"<>"))*(COUNTIFS(Inputs!$Q$2:$Q$156,"A01|"&$A7,Inputs!$I$2:$I$156,"<>"))*(COUNTIFS(Inputs!$Q$2:$Q$156,"A04|"&$A7,Inputs!$I$2:$I$156,"<>"))=0,"PENDING",IF(ABS(SUMIFS(Inputs!$J$2:$J$156,Inputs!$Q$2:$Q$156,"A03|"&$A7)/SUMIFS(Inputs!$J$2:$J$156,Inputs!$Q$2:$Q$156,"A01|"&$A7)*100-SUMIFS(Inputs!$J$2:$J$156,Inputs!$Q$2:$Q$156,"A04|"&$A7))<=0.15,"OK","CHECK")) -> OK | G7: =IF((COUNTIFS(Inputs!$Q$2:$Q$156,"A01|"&$A7,Inputs!$I$2:$I$156,"<>"))*(COUNTIFS(Inputs!$Q$2:$Q$156,"O06|"&$A7,Inputs!$I$2:$I$156,"<>"))=0,IF(COUNTIFS(Inputs!$Q$2:$Q$156,"O06|"&$A7,Inputs!$I$2:$I$156,"",Inputs!$P$2:$P$156,"<>")>0,"N/A (blank - see Inputs note)","PENDING"),IF(ABS(SUMIFS(Inputs!$J$2:$J$156,Inputs!$Q$2:$Q$156,"A01|"&$A7)*1000/INDEX(FS_Reference!$D$2:$D$10,MATCH($A7,FS_Reference!$A$2:$A$10,0))-SUMIFS(Inputs!$J$2:$J$156,Inputs!$Q$2:$Q$156,"O06|"&$A7))<=1.5,"OK","CHECK")) -> OK | H7: =IF((COUNTIFS(Inputs!$Q$2:$Q$156,"B01|"&$A7,Inputs!$I$2:$I$156,"<>"))*(COUNTIFS(Inputs!$Q$2:$Q$156,"B02|"&$A7,Inputs!$I$2:$I$156,"<>"))*(COUNTIFS(Inputs!$Q$2:$Q$156,"B03|"&$A7,Inputs!$I$2:$I$156,"<>"))*(COUNTIFS(Inputs!$Q$2:$Q$156,"B04|"&$A7,Inputs!$I$2:$I$156,"<>"))=0,"PENDING",IF(ABS(INDEX(FS_Reference!$C$2:$C$10,MATCH("FY_2024",FS_Reference!$A$2:$A$10,0))+SUMIFS(Inputs!$J$2:$J$156,Inputs!$Q$2:$Q$156,"B01|"&$A7)+SUMIFS(Inputs!$J$2:$J$156,Inputs!$Q$2:$Q$156,"B02|"&$A7)+SUMIFS(Inputs!$J$2:$J$156,Inputs!$Q$2:$Q$156,"B03|"&$A7)+SUMIFS(Inputs!$J$2:$J$156,Inputs!$Q$2:$Q$156,"B04|"&$A7)-INDEX(FS_Reference!$C$2:$C$10,MATCH($A7,FS_Reference!$A$2:$A$10,0)))<=$L7,"OK","CHECK")) -> OK | I7: =IF(COUNTIFS(Inputs!$Q$2:$Q$156,"B03|"&$A7,Inputs!$I$2:$I$156,"<>")=0,"PENDING",IF(ABS(INDEX(FS_Reference!$H$2:$H$10,MATCH($A7,FS_Reference!$A$2:$A$10,0))-INDEX(FS_Reference!$H$2:$H$10,MATCH("FY_2024",FS_Reference!$A$2:$A$10,0))-SUMIFS(Inputs!$J$2:$J$156,Inputs!$Q$2:$Q$156,"B03|"&$A7))<=$L7/2,"OK","CHECK")) -> OK | J7: =IF(COUNTIFS(Inputs!$Q$2:$Q$156,"B04|"&$A7,Inputs!$I$2:$I$156,"<>")=0,"PENDING",IF(ABS(INDEX(FS_Reference!$I$2:$I$10,MATCH($A7,FS_Reference!$A$2:$A$10,0))-INDEX(FS_Reference!$I$2:$I$10,MATCH("FY_2024",FS_Reference!$A$2:$A$10,0))-SUMIFS(Inputs!$J$2:$J$156,Inputs!$Q$2:$Q$156,"B04|"&$A7))<=$L7/2,"OK","CHECK")) -> OK | K7: =IF((COUNTIFS(Inputs!$Q$2:$Q$156,"B01|"&$A7,Inputs!$I$2:$I$156,"<>"))*(COUNTIFS(Inputs!$Q$2:$Q$156,"B02|"&$A7,Inputs!$I$2:$I$156,"<>"))=0,"PENDING",IF(ABS(INDEX(FS_Reference!$G$2:$G$10,MATCH($A7,FS_Reference!$A$2:$A$10,0))-INDEX(FS_Reference!$G$2:$G$10,MATCH("FY_2024",FS_Reference!$A$2:$A$10,0))-SUMIFS(Inputs!$J$2:$J$156,Inputs!$Q$2:$Q$156,"B01|"&$A7)-SUMIFS(Inputs!$J$2:$J$156,Inputs!$Q$2:$Q$156,"B02|"&$A7))<=$L7,"OK","CHECK")) -> OK | L7: 50 | M7: =COUNTIFS(Inputs!$D$2:$D$156,$A7,Inputs!$I$2:$I$156,"<>") -> 25 | N7: =COUNTIFS(Inputs!$D$2:$D$156,$A7,Inputs!$I$2:$I$156,"",Inputs!$P$2:$P$156,"<>") -> 1 | O7: =COUNTIFS(Inputs!$D$2:$D$156,$A7) -> 26
A8: H1_2026 | B8: =IF((COUNTIFS(Inputs!$Q$2:$Q$156,"A05|"&$A8,Inputs!$I$2:$I$156,"<>"))*(COUNTIFS(Inputs!$Q$2:$Q$156,"A06|"&$A8,Inputs!$I$2:$I$156,"<>"))*(COUNTIFS(Inputs!$Q$2:$Q$156,"A08|"&$A8,Inputs!$I$2:$I$156,"<>"))=0,"PENDING",IF(ABS(SUMIFS(Inputs!$J$2:$J$156,Inputs!$Q$2:$Q$156,"A05|"&$A8)-SUMIFS(Inputs!$J$2:$J$156,Inputs!$Q$2:$Q$156,"A06|"&$A8)-SUMIFS(Inputs!$J$2:$J$156,Inputs!$Q$2:$Q$156,"A08|"&$A8))<=2,"OK","CHECK")) -> OK | C8: =IF((COUNTIFS(Inputs!$Q$2:$Q$156,"A05|"&$A8,Inputs!$I$2:$I$156,"<>"))*(COUNTIFS(Inputs!$Q$2:$Q$156,"A06|"&$A8,Inputs!$I$2:$I$156,"<>"))*(COUNTIFS(Inputs!$Q$2:$Q$156,"A07|"&$A8,Inputs!$I$2:$I$156,"<>"))=0,"PENDING",IF(ABS(SUMIFS(Inputs!$J$2:$J$156,Inputs!$Q$2:$Q$156,"A06|"&$A8)/SUMIFS(Inputs!$J$2:$J$156,Inputs!$Q$2:$Q$156,"A05|"&$A8)*100-SUMIFS(Inputs!$J$2:$J$156,Inputs!$Q$2:$Q$156,"A07|"&$A8))<=0.2,"OK","CHECK")) -> OK | D8: =IF((COUNTIFS(Inputs!$Q$2:$Q$156,"A12|"&$A8,Inputs!$I$2:$I$156,"<>"))*(COUNTIFS(Inputs!$Q$2:$Q$156,"A09|"&$A8,Inputs!$I$2:$I$156,"<>"))*(COUNTIFS(Inputs!$Q$2:$Q$156,"A11|"&$A8,Inputs!$I$2:$I$156,"<>"))=0,"PENDING",IF(ABS(SUMIFS(Inputs!$J$2:$J$156,Inputs!$Q$2:$Q$156,"A12|"&$A8)-SUMIFS(Inputs!$J$2:$J$156,Inputs!$Q$2:$Q$156,"A09|"&$A8)-SUMIFS(Inputs!$J$2:$J$156,Inputs!$Q$2:$Q$156,"A11|"&$A8))<=2,"OK","CHECK")) -> OK | E8: =IF((COUNTIFS(Inputs!$Q$2:$Q$156,"A03|"&$A8,Inputs!$I$2:$I$156,"<>"))*(COUNTIFS(Inputs!$Q$2:$Q$156,"A02|"&$A8,Inputs!$I$2:$I$156,"<>"))*(COUNTIFS(Inputs!$Q$2:$Q$156,"A12|"&$A8,Inputs!$I$2:$I$156,"<>"))=0,"PENDING",IF(ABS(SUMIFS(Inputs!$J$2:$J$156,Inputs!$Q$2:$Q$156,"A03|"&$A8)-SUMIFS(Inputs!$J$2:$J$156,Inputs!$Q$2:$Q$156,"A02|"&$A8)-SUMIFS(Inputs!$J$2:$J$156,Inputs!$Q$2:$Q$156,"A12|"&$A8))<=60,"OK","CHECK")) -> OK | F8: =IF((COUNTIFS(Inputs!$Q$2:$Q$156,"A03|"&$A8,Inputs!$I$2:$I$156,"<>"))*(COUNTIFS(Inputs!$Q$2:$Q$156,"A01|"&$A8,Inputs!$I$2:$I$156,"<>"))*(COUNTIFS(Inputs!$Q$2:$Q$156,"A04|"&$A8,Inputs!$I$2:$I$156,"<>"))=0,"PENDING",IF(ABS(SUMIFS(Inputs!$J$2:$J$156,Inputs!$Q$2:$Q$156,"A03|"&$A8)/SUMIFS(Inputs!$J$2:$J$156,Inputs!$Q$2:$Q$156,"A01|"&$A8)*100-SUMIFS(Inputs!$J$2:$J$156,Inputs!$Q$2:$Q$156,"A04|"&$A8))<=0.15,"OK","CHECK")) -> OK | G8: =IF((COUNTIFS(Inputs!$Q$2:$Q$156,"A01|"&$A8,Inputs!$I$2:$I$156,"<>"))*(COUNTIFS(Inputs!$Q$2:$Q$156,"O06|"&$A8,Inputs!$I$2:$I$156,"<>"))=0,IF(COUNTIFS(Inputs!$Q$2:$Q$156,"O06|"&$A8,Inputs!$I$2:$I$156,"",Inputs!$P$2:$P$156,"<>")>0,"N/A (blank - see Inputs note)","PENDING"),IF(ABS(SUMIFS(Inputs!$J$2:$J$156,Inputs!$Q$2:$Q$156,"A01|"&$A8)*1000/INDEX(FS_Reference!$D$2:$D$10,MATCH($A8,FS_Reference!$A$2:$A$10,0))-SUMIFS(Inputs!$J$2:$J$156,Inputs!$Q$2:$Q$156,"O06|"&$A8))<=1.5,"OK","CHECK")) -> OK | H8: =IF((COUNTIFS(Inputs!$Q$2:$Q$156,"B01|"&$A8,Inputs!$I$2:$I$156,"<>"))*(COUNTIFS(Inputs!$Q$2:$Q$156,"B02|"&$A8,Inputs!$I$2:$I$156,"<>"))*(COUNTIFS(Inputs!$Q$2:$Q$156,"B03|"&$A8,Inputs!$I$2:$I$156,"<>"))*(COUNTIFS(Inputs!$Q$2:$Q$156,"B04|"&$A8,Inputs!$I$2:$I$156,"<>"))=0,"PENDING",IF(ABS(INDEX(FS_Reference!$C$2:$C$10,MATCH("H1_2025",FS_Reference!$A$2:$A$10,0))+SUMIFS(Inputs!$J$2:$J$156,Inputs!$Q$2:$Q$156,"B01|"&$A8)+SUMIFS(Inputs!$J$2:$J$156,Inputs!$Q$2:$Q$156,"B02|"&$A8)+SUMIFS(Inputs!$J$2:$J$156,Inputs!$Q$2:$Q$156,"B03|"&$A8)+SUMIFS(Inputs!$J$2:$J$156,Inputs!$Q$2:$Q$156,"B04|"&$A8)-INDEX(FS_Reference!$C$2:$C$10,MATCH($A8,FS_Reference!$A$2:$A$10,0)))<=$L8,"OK","CHECK")) -> OK | I8: =IF(COUNTIFS(Inputs!$Q$2:$Q$156,"B03|"&$A8,Inputs!$I$2:$I$156,"<>")=0,"PENDING",IF(ABS(INDEX(FS_Reference!$H$2:$H$10,MATCH($A8,FS_Reference!$A$2:$A$10,0))-INDEX(FS_Reference!$H$2:$H$10,MATCH("H1_2025",FS_Reference!$A$2:$A$10,0))-SUMIFS(Inputs!$J$2:$J$156,Inputs!$Q$2:$Q$156,"B03|"&$A8))<=$L8/2,"OK","CHECK")) -> OK | J8: =IF(COUNTIFS(Inputs!$Q$2:$Q$156,"B04|"&$A8,Inputs!$I$2:$I$156,"<>")=0,"PENDING",IF(ABS(INDEX(FS_Reference!$I$2:$I$10,MATCH($A8,FS_Reference!$A$2:$A$10,0))-INDEX(FS_Reference!$I$2:$I$10,MATCH("H1_2025",FS_Reference!$A$2:$A$10,0))-SUMIFS(Inputs!$J$2:$J$156,Inputs!$Q$2:$Q$156,"B04|"&$A8))<=$L8/2,"OK","CHECK")) -> OK | K8: =IF((COUNTIFS(Inputs!$Q$2:$Q$156,"B01|"&$A8,Inputs!$I$2:$I$156,"<>"))*(COUNTIFS(Inputs!$Q$2:$Q$156,"B02|"&$A8,Inputs!$I$2:$I$156,"<>"))=0,"PENDING",IF(ABS(INDEX(FS_Reference!$G$2:$G$10,MATCH($A8,FS_Reference!$A$2:$A$10,0))-INDEX(FS_Reference!$G$2:$G$10,MATCH("H1_2025",FS_Reference!$A$2:$A$10,0))-SUMIFS(Inputs!$J$2:$J$156,Inputs!$Q$2:$Q$156,"B01|"&$A8)-SUMIFS(Inputs!$J$2:$J$156,Inputs!$Q$2:$Q$156,"B02|"&$A8))<=$L8,"OK","CHECK")) -> OK | L8: 50 | M8: =COUNTIFS(Inputs!$D$2:$D$156,$A8,Inputs!$I$2:$I$156,"<>") -> 25 | N8: =COUNTIFS(Inputs!$D$2:$D$156,$A8,Inputs!$I$2:$I$156,"",Inputs!$P$2:$P$156,"<>") -> 0 | O8: =COUNTIFS(Inputs!$D$2:$D$156,$A8) -> 25
A10: Total | M10: =SUM(M2:M8) -> 154 | N10: =SUM(N2:N8) -> 1 | O10: =SUM(O2:O8) -> 155
A12: Double_checked status (counted from Inputs column O)
A13: Y | B13: =COUNTIF(Inputs!$O$2:$O$156,"Y") -> 151
A14: N | B14: =COUNTIF(Inputs!$O$2:$O$156,"N") -> 3
A15: N/A | B15: =COUNTIF(Inputs!$O$2:$O$156,"N/A") -> 1
A16: Total | B16: =SUM(B13:B15) -> 155
